Workbook
Name ____ANS2: #REF!
Name ___ANS1: #REF!
Name ___ANS2: #REF!
Name ___FIR1: [1]建築!#REF!
Name ___KEI1: #REF!
Name ___KEI2: #REF!
Name ___KEI3: #REF!
Name ___RE2: #REF!
Name ___SEC1: [1]建築!#REF!
Name ___sen1: #REF!
Name ___sen2: #REF!
Name ___sen3: #REF!
Name ___sen4: #REF!
Name ___SUB2: #REF!
Name ___SUB3: #REF!
Name ___SUB4: #REF!
Name ___SUM3: [1]建築!#REF!
Name ___T1: #REF!
Name ___TC1: #REF!
Name ___TTL01: #REF!
Name ___TTL02: #REF!
Name ___TTL03: #REF!
Name ___TTL1: #REF!
Name ___TTL2: #REF!
Name ___TTL3: #REF!
Name ___TTL5: #REF!
Name ___TTL51: #REF!
Name ___TTL52: #REF!
Name ___TTL53: #REF!
Name __ANS1: #REF!
Name __ANS2: #REF!
Name __FIR1: [1]建築!#REF!
Name __KEI1: #REF!
Name __KEI2: #REF!
Name __KEI3: #REF!
Name __RE2: #REF!
Name __SEC1: [1]建築!#REF!
Name __sen1: #REF!
Name __sen2: #REF!
Name __sen3: #REF!
Name __sen4: #REF!
Name __SUB2: #REF!
Name __SUB3: #REF!
Name __SUB4: #REF!
Name __SUM3: [1]建築!#REF!
Name __T1: #REF!
Name __TC1: #REF!
Name __TTL01: #REF!
Name __TTL02: #REF!
Name __TTL03: #REF!
Name __TTL1: #REF!
Name __TTL2: #REF!
Name __TTL3: #REF!
Name __TTL5: #REF!
Name __TTL51: #REF!
Name __TTL52: #REF!
Name __TTL53: #REF!
Name _0: [2]建築!#REF!
Name _0: [2]建築!#REF!
Name _0: [2]建築!#REF!

Sheet 表紙
A2: 輪教工第 号
A3: 令和 ６ 年度 | R3: 設
R4: 計
A12: 大藪小学校屋内運動場空調設備設置工事
A13: 設計書
A21: 工事 場所 | D21: 輪之内町地内 | K21: 施工方法 | N21: 請負
A22: 設計年月日 | K22: 施工期間
A23: 起工年月日 | K23: 竣工年月日

Sheet 総括
B2: 名 称 | C2: 仕 様 | D2: 数量 | E2: 単位 | F2: 単価 | G2: 金額 | H2: 摘要
B3: 大藪小学校屋内運動場空調設備設置工事
A5: Ⅰ | B5: 直接工事費 | D5: 1 | E5: 式 | G5: ='A+B+C'!G22 -> 91602532
B6: 直接工事費計 | D6: 1 | E6: 式 | G6: =G5 -> 91602532
A8: Ⅱ | B8: 共通仮設費 | C8: 直接工事費計×共通仮設率 | D8: 1 | E8: 式 | G8: =G6*(H8*100)/100 -> 2702274.7 | H8: 0.0295
B9: 共通仮設費(積上げ) | D9: 1 | E9: 式 | G9: 357100
B10: 共通仮設費 | D10: 1 | E10: 式 | G10: =G8 -> 2702274.7
B11: 純工事費計 | G11: =G6+G10 -> 94304807
A13: Ⅲ | B13: 現場管理費 | C13: 純工事費計×現場管理費率 | D13: 1 | E13: 式 | G13: =G11*(H13*100)/100 -> 13495018 | H13: 0.1431
B14: 工事原価 | G14: =G11+G13 -> 1.0779982e+08
A16: Ⅳ | B16: 一般管理費 | C16: 工事原価×一般管理費率 | D16: 1 | E16: 式 | G16: =G14*(H16*100)/100 -> 12655699 | H16: 0.1174
B17: 工事価格 | G17: =G14+G16 -> 1.2045552e+08
B19: 改め総計 | D19: 1 | E19: 式 | G19: =ROUNDDOWN(G17,-4) -> 120450000
A21: Ⅴ | B21: 消費税類及び地方消費税 | C21: 10％ | D21: 1 | E21: 式 | G21: =G19*(H21*100)/100 -> 12045000 | H21: 0.1
B23: 総合計
G24: =G19+G21 -> 132495000
D25: 設計･監理 株式会社 大幸建築設計事務所 | H25: 1

Sheet A+B+C
B2: 名 称 | C2: 仕 様 | D2: 数量 | E2: 単位 | F2: 単価 | G2: 金額 | H2: 摘要
B3: 空調設備改修工事
A5: A | B5: 空調設備改修工事 | D5: 1 | E5: 式 | G5: ='A空調－計 '!G22 -> 78335210
A6: B | B6: 電気設備工事 | D6: 1 | E6: 式 | G6: ='Ｂ電気－計'!G20 -> 5401173
A7: Ｃ | B7: 付帯建築工事 | D7: 1 | E7: 式 | G7: ='Ｃ付帯－計'!G20 -> 7866149
B22: 計 | G22: =SUM(G5:G9) -> 91602532
D24: 設計･監理 株式会社 大幸建築設計事務所 | H24: =ROWS($H$1:H24)/24+1 -> 2

Sheet A空調－計 
B2: 名 称 | C2: 仕 様 | D2: 数量 | E2: 単位 | F2: 単価 | G2: 金額 | H2: 摘要
A3: 1 | B3: 空調設備改修工事
A5: 1- 1． | B5: 空調設備機器工事 | D5: 1 | E5: 式 | G5: ='空調(明細)'!G70 -> 37584400
A6: 1- 2． | B6: 空調設備配管工事 | C6: 給水配管工事含む | D6: 1 | E6: 式 | G6: ='空調(明細)'!G118 -> 27898200
A7: 1- 3． | B7: 自動制御設備工事 | D7: 1 | E7: 式 | G7: ='空調(明細)'!G166 -> 5982450
A8: 1- 4． | B8: ガス設備工事 | D8: 1 | E8: 式 | G8: ='空調(明細)'!G214 -> 6870160
B22: 計 | G22: =SUM(G5:G21) -> 78335210
D24: 設計･監理 株式会社 大幸建築設計事務所 | H24: 3

Sheet 空調(明細)
B2: 名 称 | C2: 仕 様 | D2: 数量 | E2: 単位 | F2: 単価 | G2: 金額 | H2: 備考
A3: 1-1 | B3: 空調設備機器工事
B4: GHP-1
B5: ｶﾞｽﾋｰﾄﾎﾟﾝﾌﾟﾊﾟｯｹｰｼﾞｴｱｺﾝ20㏋ | C5: 自立型 室外機 | D5: 1 | E5: 台 | F5: ='GHP空調機-複単'!U10 -> 8650000 | G5: =ROUNDDOWN(D5*F5,0) -> 8650000 | H5: 空調機複合単価
B6: 冷房 56.0kw | C6: 付属品 自立ユニット（切替盤）
B7: 暖房 63.0kw
B9: GHP-1-1～4
B10: ｶﾞｽﾋｰﾄﾎﾟﾝﾌﾟﾊﾟｯｹｰｼﾞｴｱｺﾝ | C10: 室内機－天井吊形 | D10: 4 | E10: 台 | F10: ='GHP空調機-複単'!U11 -> 653000 | G10: =ROUNDDOWN(D10*F10,0) -> 2612000 | H10: 空調機複合単価
B11: 冷房 14.0kw
B12: 暖房 16.0kw
B14: GHP-2
B15: ｶﾞｽﾋｰﾄﾎﾟﾝﾌﾟﾊﾟｯｹｰｼﾞｴｱｺﾝ20㏋ | C15: 自立型 室外機 | D15: 1 | E15: 台 | F15: ='GHP空調機-複単'!U12 -> 7380000 | G15: =ROUNDDOWN(D15*F15,0) -> 7380000 | H15: 空調機複合単価
B16: 冷房 56.0kw
B17: 暖房 63.0kw
B19: GHP-2-1～4
B20: ｶﾞｽﾋｰﾄﾎﾟﾝﾌﾟﾊﾟｯｹｰｼﾞｴｱｺﾝ | C20: 室内機－天井吊形 | D20: 4 | E20: 台 | F20: ='GHP空調機-複単'!U13 -> 653000 | G20: =ROUNDDOWN(D20*F20,0) -> 2612000 | H20: 空調機複合単価
B21: 冷房 14.0kw
B22: 暖房 16.0kw
D24: 設計･監理 株式会社 大幸建築設計事務所 | H24: ='A空調－計 '!H24+1 -> 4
B26: 名 称 | C26: 仕 様 | D26: 数量 | E26: 単位 | F26: 単価 | G26: 金額 | H26: 備考
B27: GHP-3
B28: ｶﾞｽﾋｰﾄﾎﾟﾝﾌﾟﾊﾟｯｹｰｼﾞｴｱｺﾝ20㏋ | C28: 自立型 室外機 | D28: 1 | E28: 台 | F28: ='GHP空調機-複単'!U14 -> 7380000 | G28: =ROUNDDOWN(D28*F28,0) -> 7380000 | H28: 空調機複合単価
B29: 冷房 56.0kw
B30: 暖房 63.0kw
B32: GHP-3-1～4
B33: ｶﾞｽﾋｰﾄﾎﾟﾝﾌﾟﾊﾟｯｹｰｼﾞｴｱｺﾝ | C33: 室内機－天井吊形 | D33: 4 | E33: 台 | F33: ='GHP空調機-複単'!U15 -> 653000 | G33: =ROUNDDOWN(D33*F33,0) -> 2612000 | H33: 空調機複合単価
B34: 冷房 14.0kw
B35: 暖房 16.0kw
B37: GHP-4
B38: ｶﾞｽﾋｰﾄﾎﾟﾝﾌﾟﾊﾟｯｹｰｼﾞｴｱｺﾝ10㏋ | C38: 室外機 | D38: 1 | E38: 台 | F38: ='GHP空調機-複単'!U16 -> 3420000 | G38: =ROUNDDOWN(D38*F38,0) -> 3420000 | H38: 空調機複合単価
B39: 冷房 28.0kw
B40: 暖房 31.5kw
B42: GHP-4-1～3
B43: ｶﾞｽﾋｰﾄﾎﾟﾝﾌﾟﾊﾟｯｹｰｼﾞｴｱｺﾝ | C43: 室内機－天井カセット形 | D43: 3 | E43: 台 | F43: ='GHP空調機-複単'!U17 -> 653000 | G43: =ROUNDDOWN(D43*F43,0) -> 1959000 | H43: 空調機複合単価
B44: 冷房 9.0kw
B45: 暖房 10.0kw
G46: =SUM(H45) -> 0
D48: 設計･監理 株式会社 大幸建築設計事務所 | H48: =+H24+1 -> 5
B50: 名 称 | C50: 仕 様 | D50: 数量 | E50: 単位 | F50: 単価 | G50: 金額 | H50: 備考
B51: ワイヤードリモコン | C51: 計装設備に支給 | D51: 6 | E51: 個 | F51: ='GHP空調機-複単'!U22 -> 33600 | G51: =ROUNDDOWN(D51*F51,0) -> 201600 | H51: 空調機複合単価
...

Sheet Ｂ電気－計
I1: 1
B2: 名 称 | C2: 仕 様 | D2: 数量 | E2: 単位 | F2: 単価 | G2: 金額 | H2: 備考 | I2: 単価
A3: Ｂ | B3: 電気設備工事
A5: 1 | B5: 電灯幹線設備工事 | D5: 1 | E5: 式 | G5: =+'電気（明細）'!G72 -> 5401173
B20: 計 | G20: =SUM(G3:G19) -> 5401173
D24: 設計･監理 株式会社 大幸建築設計事務所 | H24: 14

Sheet 電気（明細）
B2: 名 称 | C2: 仕 様 | D2: 数量 | E2: 単位 | F2: 単価 | G2: 金額 | H2: 備考
B3: 電気設備工事
B4: 電灯幹線設備工事
B5: 電線管 | C5: GP-22 露出 溶融亜鉛メッキ | D5: 26 | E5: ⅿ | F5: 4840 | G5: =D5*F5 -> 125840 | H5: 積算マニュアル電気
B6: 電線管 | C6: GP-28 露出 溶融亜鉛メッキ | D6: 8 | E6: ⅿ | F6: 6320 | G6: =D6*F6 -> 50560 | H6: 積算マニュアル電気
B7: 電線管 | C7: GP-42 露出 溶融亜鉛メッキ | D7: 15 | E7: ⅿ | F7: 10100 | G7: =D7*F7 -> 151500 | H7: 積算マニュアル電気
B8: 電線管 | C8: GP-54 露出 溶融亜鉛メッキ | D8: 43 | E8: ⅿ | F8: 13800 | G8: =D8*F8 -> 593400 | H8: 積算マニュアル電気
B9: 電線管 | C9: ＥP-25 隠ぺい（天井内） | D9: 65 | E9: ⅿ | F9: 2910 | G9: =D9*F9 -> 189150 | H9: 積算マニュアル電気
B10: 電線管 | C10: ＥP-31 隠ぺい（天井内） | D10: 25 | E10: ⅿ | F10: 3770 | G10: =D10*F10 -> 94250 | H10: 積算マニュアル電気
B11: 電線管 | C11: ＥP-39 隠ぺい（天井内） | D11: 19 | E11: ⅿ | F11: 4570 | G11: =D11*F11 -> 86830 | H11: 積算マニュアル電気
B12: 電線管 | C12: ＥP-51 隠ぺい（天井内） | D12: 31 | E12: ⅿ | F12: 6250 | G12: =D12*F12 -> 193750 | H12: 積算マニュアル電気
B13: 電線管 | C13: CP-25 露出 塗装あり | D13: 25 | E13: ⅿ | F13: 4320 | G13: =D13*F13 -> 108000 | H13: 積算マニュアル電気 管4,030+塗装290
B14: 電線管 | C14: CP-51 露出 塗装あり | D14: 4 | E14: ⅿ | F14: 9140 | G14: =D14*F14 -> 36560 | H14: 積算マニュアル電気 管8,550+塗装590
B15: 電線管 | C15: HIVE16 露出 | D15: 6 | E15: ⅿ | F15: 2390 | G15: =D15*F15 -> 14340 | H15: 積算マニュアル電気
B16: 金属製可とう電線管 | C16: F-24 ビニル被覆（防水）付属品共 | D16: 17 | E16: か所 | F16: 2260 | G16: =D16*F16 -> 38420 | H16: 積算マニュアル電気
... B24: プルボックス | C24: 250×250×200 錆止め | D24: 6 | E24: 個 | F24: 19000 | G24: =D24*F24 -> 114000 | H24: 積算マニュアル電気
D25: 設計･監理 株式会社 大幸建築設計事務所 | H25: =+'Ｂ電気－計'!H24+1 -> 15
B27: 名 称 | C27: 仕 様 | D27: 数量 | E27: 単位 | F27: 単価 | G27: 金額 | H27: 備考
B28: プルボックス | C28: 150×150×150 SUS WP | D28: 2 | E28: 個 | F28: 16400 | G28: =D28*F28 -> 32800 | H28: 積算マニュアル電気
B29: プルボックス | C29: 300×300×200 SUS WP | D29: 3 | E29: 個 | F29: 37200 | G29: =D29*F29 -> 111600 | H29: 積算マニュアル電気
B30: プルボックス | C30: 500×500×300 SUS WP | D30: 1 | E30: 個 | F30: 79600 | G30: =D30*F30 -> 79600 | H30: 積算マニュアル電気
B31: 電線 | C31: EM-IE 5.5sq 管内 | D31: 16 | E31: ⅿ | F31: 800 | G31: =D31*F31 -> 12800 | H31: 積算マニュアル電気
B32: ケーブル | C32: EM-CE 2.0sq-3C 管内 | D32: 11 | E32: ⅿ | F32: 1040 | G32: =D32*F32 -> 11440 | H32: 積算マニュアル電気
B33: ケーブル | C33: EM-CE 3.5sq-3C 管内 | D33: 610 | E33: ⅿ | F33: 1390 | G33: =D33*F33 -> 847900 | H33: 積算マニュアル電気
B34: ケーブル | C34: EM-CE 14sq-2C 管内 | D34: 9 | E34: ⅿ | F34: 2300 | G34: =D34*F34 -> 20700 | H34: 積算マニュアル電気
B35: ケーブル | C35: EM-CET 38sq 管内 | D35: 12 | E35: ⅿ | F35: 6230 | G35: =D35*F35 -> 74760 | H35: 積算マニュアル電気
B36: 新設空調電源盤 | C36: L-AC 屋外自立型 WP・SUS | D36: 1 | E36: 面 | F36: 1090000 | G36: =D36*F36 -> 1090000 | H36: メーカー定価×0.8
B37: 新設開閉器盤 | C37: S-AC 屋外壁掛型 WP・SUS | D37: 1 | E37: 面 | F37: 114000 | G37: =D37*F37 -> 114000 | H37: メーカー定価×0.8
B38: 医用コンセント | C38: 2P15A×1 接地極付 赤色（非常用） | D38: 3 | E38: 個 | F38: 4600 | G38: =D38*F38 -> 13800 | H38: 積算マニュアル電気
B39: 防水コンセント | C39: 2P15A×1 抜け止め・接地端子付 | D39: 1 | E39: 個 | F39: 4010 | G39: =D39*F39 -> 4010 | H39: 積算マニュアル電気
... B45: 機械はつり | C45: φ150 200mm | D45: 1 | E45: か所 | F45: 25400 | G45: =D45*F45 -> 25400 | H45: 積算マニュアル電気
B46: 点検調査費 | C46: 中部電気保安協会 | D46: 1 | E46: 式 | F46: 85000 | G46: =D46*F46 -> 85000
D50: 設計･監理 株式会社 大幸建築設計事務所 | H50: =+H25+1 -> 16
B52: 名 称 | C52: 仕 様 | D52: 数量 | E52: 単位 | F52: 単価 | G52: 金額 | H52: 備考
B53: 外灯移設工事 | C53: 既設外灯を東へ約2.5m移設
B54: 外灯撤去 | C54: ポール灯 取外し・再使用品保管 | D54: 1 | E54: 基 | F54: 22900 | G54: =D54*F54 -> 22900 | H54: 積算マニュアル電気 撤去費
B55: 根切り | C55: 人力（基礎部 2.0・配管部 2.5×0.4×0.6） | D55: 2.6 | E55: ㎥ | F55: 14600 | G55: =D55*F55 -> 37960 | H55: 積算マニュアル電気
B56: 埋戻し | C56: 人力 | D56: 2.2 | E56: ㎥ | F56: 11100 | G56: =D56*F56 -> 24420 | H56: 積算マニュアル電気
B57: 建設発生土処理 | C57: 人力（場内敷ならし） | D57: 0.4 | E57: ㎥ | F57: 8590 | G57: =D57*F57 -> 3436 | H57: 積算マニュアル電気
B58: 砂利地業 | C58: 基礎下 | D58: 0.1 | E58: ㎥ | F58: 9670 | G58: =D58*F58 -> 967 | H58: 積算マニュアル電気
...

Sheet Ｃ付帯－計
I1: 1
B2: 名 称 | C2: 仕 様 | D2: 数量 | E2: 単位 | F2: 単価 | G2: 金額 | H2: 備考 | I2: 単価
A3: Ｃ | B3: 付帯建築工事
A5: 1 | B5: 付帯建築工事 | D5: 1 | E5: 式 | G5: ='付帯（明細）'!G23 -> 7866149
B20: 計 | G20: =SUM(G3:G19) -> 7866149
D24: 設計･監理 株式会社 大幸建築設計事務所 | H24: 18

Sheet 付帯（明細）
B2: 名 称 | C2: 仕 様 | D2: 数量 | E2: 単位 | F2: 単価 | G2: 金額 | H2: 備考
A3: Ｃ | B3: 付帯建築工事
B4: 1.直接仮設 | D4: 1 | E4: 式 | F4: 2012774 | G4: 2012774
B5: 2.撤去工事 | D5: 1 | E5: 式 | F5: 817981 | G5: 817981
B6: 3.室外機置場建築工事 | D6: 1 | E6: 式 | F6: 5035394 | G6: 5035394
B23: 合計 | G23: =SUM(G4:G21) -> 7866149
D25: 設計･監理 株式会社 大幸建築設計事務所 | H25: =+'Ｃ付帯－計'!H24+1 -> 19
B27: 名 称 | C27: 仕 様 | D27: 数量 | E27: 単位 | F27: 単価 | G27: 金額 | H27: 備考
A28: C | B28: 1.直接仮設
B29: やりかた | C29: RC造 | D29: 34.4 | E29: ㎡ | F29: 230 | G29: =D29*F29 -> 7912
B30: 墨出し | C30: 室外機置場 | D30: 34.4 | E30: ㎡ | F30: 450 | G30: =D30*F30 -> 15480
B31: 養生 | C31: 室外機置場 | D31: 34.4 | E31: ｍ | F31: 310 | G31: =D31*F31 -> 10664
B32: 床養生 | C32: ﾐｰﾃｨﾝｸﾞ･ｱﾘｰﾅ･ｷﾞｬﾗﾘｰ | D32: 993 | E32: ㎡ | F32: 210 | G32: =D32*F32 -> 208530
B33: 清掃型付 | C33: 室外機置場 | D33: 34.4 | E33: ㎡ | F33: 780 | G33: =D33*F33 -> 26832
B34: 清掃型付 | C34: ﾐｰﾃｨﾝｸﾞ･ｱﾘｰﾅ･ｷﾞｬﾗﾘｰ | D34: 993 | E34: ㎡ | F34: 780 | G34: =D34*F34 -> 774540
B35: 竣工清掃 | C35: 室外機置場 | D35: 34.4 | E35: ㎡ | F35: 440 | G35: =D35*F35 -> 15136
B36: 外部足場 | C36: クサビ足場 ３ヶ月 | D36: 373 | E36: ㎡ | F36: 1780 | G36: =D36*F36 -> 663940
B37: 養生シート | D37: 373 | E37: ㎡ | F37: 540 | G37: =D37*F37 -> 201420
B38: 内部足場 | C38: 脚立足場 | D38: 192 | E38: ㎡ | F38: 460 | G38: =D38*F38 -> 88320
B48: 小計 | G48: =SUM(G29:G47) -> 2012774
D50: 設計･監理 株式会社 大幸建築設計事務所 | H50: =+H25+1 -> 20
B52: 名 称 | C52: 仕 様 | D52: 数量 | E52: 単位 | F52: 単価 | G52: 金額 | H52: 備考
A53: C | B53: 2.撤去工事
B54: 樹木撤去 | D54: 1 | E54: 式 | F54: 105000 | G54: =D54*F54 -> 105000 | H54: 見積×0.7
B55: コンクリートカッター | D55: 6 | E55: ｍ | F55: 1400 | G55: =D55*F55 -> 8400 | H55: 見積×0.7
B56: コンクリートカッター撤去 | C56: 運搬・処分共 | D56: 1.5 | E56: ｍ3 | F56: 38500 | G56: =D56*F56 -> 57750 | H56: 見積×0.7
B57: U字溝(蓋共)撤去 | C57: 運搬・処分共 | D57: 14.3 | E57: ｍ | F57: 2450 | G57: =D57*F57 -> 35035 | H57: 見積×0.7
B58: 土撤去 | C58: 運搬・処分共 | D58: 10.5 | E58: ｍ3 | F58: 10500 | G58: =D58*F58 -> 110250 | H58: 見積×0.7
B59: 重機回送費 | D59: 1 | E59: 式 | F59: 84000 | G59: =D59*F59 -> 84000 | H59: 見積×0.7
B60: ケイカル板 t12撤去 | C60: 軽鉄下地共 | D60: 77.3 | E60: ｍ2 | F60: 3520 | G60: =D60*F60 -> 272096
B61: 軽鉄下地運搬・処分費 | D61: 1 | E61: 式 | F61: 59000 | G61: =D61*F61 -> 59000 | H61: 代価1-1
B62: ケイカル板 t12運搬・処分費 | D62: 1 | E62: 式 | F62: 53900 | G62: =D62*F62 -> 53900 | H62: 代価1-2
B63: 塩ビ廻り縁撤去 | D63: 155 | E63: ｍ | F63: 210 | G63: =D63*F63 -> 32550
G64: =D64*F64 -> 0
G65: =D65*F65 -> 0
G66: =D66*F66 -> 0
G67: =D67*F67 -> 0
G68: =D68*F68 -> 0
G69: =D69*F69 -> 0
G70: =D70*F70 -> 0
...

Sheet GHP空調機-複単
A2: 工事名称： | B2: =表紙!A12 -> 大藪小学校屋内運動場空調設備設置工事
A3: 工事種別： | B3: ガスヒートポンプエアコン | J3: ※ヤンマーは自立運転制御が図面内容と異なるので見積除外とした。
A4: 掛率種別： | D4: 80 | F4: ％
B5: ガスヒートポンプエアコン | N5: 採用メーカー名称 | U5: № | V5: 1
E6: 名 称 | N6: 朝日機器(アイシン) | Q6: ② 労 務 費 | S6: ③ | T6: 複合単価
A7: 名 称 | B7: 内 容 | C7: 数量 | D7: 単位 | E7: 朝日機器(アイシン) | H7: ヤンマー | O7: 掛率 | P7: ① | Q7: 歩掛 | R7: 賃金／日 | S7: その他 | T7: ①+②+③ | U7: 決定単価 | V7: 備 考
E8: P. | F8: 単 価 | G8: 金 額 | H8: P. | I8: 単 価 | J8: 金 額 | K8: P. | L8: 単 価 | M8: 金 額 | N8: 最小価格 | P8: 採用価格 | Q8: 作業員 | S8: ②× | T8: （合 計）
O9: =D4/100 -> 0.8 | Q9: 設備機械工 | R9: 29000 | S9: 0.19
A10: 1 | B10: GHP-1＋自立ユニット＋バッテリー＋遠隔監視アダプター | C10: 1 | D10: 台 | F10: =8870000+1166000+202000+85000+14700*2+11000+198000+15000 -> 10576400 | G10: =IF(F10=0," ",C10*F10) -> 10576400 | I10: =9320000+176000+64000+250000+15400*2+11500 -> 9852300 | J10: =IF(I10=0," ",C10*I10) -> 9852300 | M10: =IF(C10=" "," ",C10*L10) -> 0 | N10: =IF($N$6=" "," ",IF($N$6=$E$7,F10,IF($N$6=$H$7,I10,IF($N$6=$K$7,L10,0)))) -> 10576400 | O10: =IF(OR(N10=" ",N10=0)," ",$O$9) -> 0.8 | P10: =IF(OR(N10=" ",N10=0)," ",+ROUNDDOWN(N10*O10,0)) -> 8461120 | Q10: 5.5 | R10: =Q10*($R$9) -> 159500 | S10: =R10*0.19 -> 30305 | T10: =+P10+R10+S10 -> 8650925 | U10: =ROUNDDOWN(T10,-4) -> 8650000
A11: 2 | B11: GHP-1-1～4 | C11: 4 | D11: 台 | F11: =782000 -> 782000 | G11: =IF(F11=0," ",C11*F11) -> 3128000 | I11: 615000 | J11: =IF(I11=0," ",C11*I11) -> 2460000 | M11: =IF(C11=" "," ",C11*L11) -> 0 | N11: =IF($N$6=" "," ",IF($N$6=$E$7,F11,IF($N$6=$H$7,I11,IF($N$6=$K$7,L11,0)))) -> 782000 | O11: =IF(OR(N11=" ",N11=0)," ",$O$9) -> 0.8 | P11: =IF(OR(N11=" ",N11=0)," ",+ROUNDDOWN(N11*O11,0)) -> 625600 | Q11: 0.82 | R11: =Q11*($R$9) -> 23780 | S11: =R11*0.19 -> 4518.2 | T11: =+P11+R11+S11 -> 653898.2 | U11: =ROUNDDOWN(T11,-3) -> 653000
A12: 3 | B12: GHP-2 | C12: 1 | D12: 台 | F12: =8870000+85000+14700*2+11000 -> 8995400 | G12: =IF(F12=0," ",C12*F12) -> 8995400 | I12: =8720000+15400*2+11500 -> 8762300 | J12: =IF(I12=0," ",C12*I12) -> 8762300 | M12: =IF(C12=" "," ",C12*L12) -> 0 | N12: =IF($N$6=" "," ",IF($N$6=$E$7,F12,IF($N$6=$H$7,I12,IF($N$6=$K$7,L12,0)))) -> 8995400 | O12: =IF(OR(N12=" ",N12=0)," ",$O$9) -> 0.8 | P12: =IF(OR(N12=" ",N12=0)," ",+ROUNDDOWN(N12*O12,0)) -> 7196320 | Q12: 5.5 | R12: =Q12*($R$9) -> 159500 | S12: =R12*0.19 -> 30305 | T12: =+P12+R12+S12 -> 7386125 | U12: =ROUNDDOWN(T12,-4) -> 7380000
A13: 4 | B13: GHP-2-1～4 | C13: 4 | D13: 台 | F13: =782000 -> 782000 | G13: =IF(F13=0," ",C13*F13) -> 3128000 | I13: 615000 | J13: =IF(I13=0," ",C13*I13) -> 2460000 | M13: =IF(C13=" "," ",C13*L13) -> 0 | N13: =IF($N$6=" "," ",IF($N$6=$E$7,F13,IF($N$6=$H$7,I13,IF($N$6=$K$7,L13,0)))) -> 782000 | O13: =IF(OR(N13=" ",N13=0)," ",$O$9) -> 0.8 | P13: =IF(OR(N13=" ",N13=0)," ",+ROUNDDOWN(N13*O13,0)) -> 625600 | Q13: 0.82 | R13: =Q13*($R$9) -> 23780 | S13: =R13*0.19 -> 4518.2 | T13: =+P13+R13+S13 -> 653898.2 | U13: =ROUNDDOWN(T13,-3) -> 653000
A14: 5 | B14: GHP-3 | C14: 1 | D14: 台 | F14: =8870000+85000+14700*2+11000 -> 8995400 | G14: =IF(F14=0," ",C14*F14) -> 8995400 | I14: =9320000+85000+15400*2+11500 -> 9447300 | J14: =IF(I14=0," ",C14*I14) -> 9447300 | M14: =IF(C14=" "," ",C14*L14) -> 0 | N14: =IF($N$6=" "," ",IF($N$6=$E$7,F14,IF($N$6=$H$7,I14,IF($N$6=$K$7,L14,0)))) -> 8995400 | O14: =IF(OR(N14=" ",N14=0)," ",$O$9) -> 0.8 | P14: =IF(OR(N14=" ",N14=0)," ",+ROUNDDOWN(N14*O14,0)) -> 7196320 | Q14: 5.5 | R14: =Q14*($R$9) -> 159500 | S14: =R14*0.19 -> 30305 | T14: =+P14+R14+S14 -> 7386125 | U14: =ROUNDDOWN(T14,-4) -> 7380000
A15: 6 | B15: GHP-3-1～4 | C15: 4 | D15: 台 | F15: 782000 | G15: =IF(F15=0," ",C15*F15) -> 3128000 | I15: 615000 | J15: =IF(I15=0," ",C15*I15) -> 2460000 | M15: =IF(C15=" "," ",C15*L15) -> 0 | N15: =IF($N$6=" "," ",IF($N$6=$E$7,F15,IF($N$6=$H$7,I15,IF($N$6=$K$7,L15,0)))) -> 782000 | O15: =IF(OR(N15=" ",N15=0)," ",$O$9) -> 0.8 | P15: =IF(OR(N15=" ",N15=0)," ",+ROUNDDOWN(N15*O15,0)) -> 625600 | Q15: 0.82 | R15: =Q15*($R$9) -> 23780 | S15: =R15*0.19 -> 4518.2 | T15: =+P15+R15+S15 -> 653898.2 | U15: =ROUNDDOWN(T15,-3) -> 653000
A16: 7 | B16: GHP-4 | C16: 1 | D16: 台 | F16: =4150000+11000 -> 4161000 | G16: =IF(F16=0," ",C16*F16) -> 4161000 | I16: =4100000+11500 -> 4111500 | J16: =IF(I16=0," ",C16*I16) -> 4111500 | M16: =IF(C16=" "," ",C16*L16) -> 0 | N16: =IF($N$6=" "," ",IF($N$6=$E$7,F16,IF($N$6=$H$7,I16,IF($N$6=$K$7,L16,0)))) -> 4161000 | O16: =IF(OR(N16=" ",N16=0)," ",$O$9) -> 0.8 | P16: =IF(OR(N16=" ",N16=0)," ",+ROUNDDOWN(N16*O16,0)) -> 3328800 | Q16: 2.84 | R16: =Q16*($R$9) -> 82360 | S16: =R16*0.19 -> 15648.4 | T16: =+P16+R16+S16 -> 3426808.4 | U16: =ROUNDDOWN(T16,-4) -> 3420000
A17: 8 | B17: GHP-4-1～3 | C17: 3 | D17: 台 | F17: 782000 | G17: =IF(F17=0," ",C17*F17) -> 2346000 | I17: 615000 | J17: =IF(I17=0," ",C17*I17) -> 1845000 | M17: =IF(C17=" "," ",C17*L17) -> 0 | N17: =IF($N$6=" "," ",IF($N$6=$E$7,F17,IF($N$6=$H$7,I17,IF($N$6=$K$7,L17,0)))) -> 782000 | O17: =IF(OR(N17=" ",N17=0)," ",$O$9) -> 0.8 | P17: =IF(OR(N17=" ",N17=0)," ",+ROUNDDOWN(N17*O17,0)) -> 625600 | Q17: 0.82 | R17: =Q17*($R$9) -> 23780 | S17: =R17*0.19 -> 4518.2 | T17: =+P17+R17+S17 -> 653898.2 | U17: =ROUNDDOWN(T17,-3) -> 653000
A22: 13 | B22: ワイヤードリモコン | C22: 4 | D22: 個 | F22: 42000 | G22: =IF(F22=0," ",C22*F22) -> 168000 | I22: 41000 | J22: =IF(I22=0," ",C22*I22) -> 164000 | M22: =IF(C22=" "," ",C22*L22) -> 0 | N22: =F22 -> 42000 | O22: =IF(OR(N22=" ",N22=0)," ",$O$9) -> 0.8 | P22: =IF(OR(N22=" ",N22=0)," ",+ROUNDDOWN(N22*O22,0)) -> 33600 | R22: =Q22*($R$9) -> 0 | S22: =R22*0.19 -> 0 | T22: =+P22+R22+S22 -> 33600 | U22: =ROUNDDOWN(T22,-2) -> 33600
A23: 14 | B23: 自立運転スイッチ＋集中設定費込み | C23: 1 | D23: 式 | F23: =101000+90000 -> 191000 | G23: =IF(F23=0," ",C23*F23) -> 191000 | N23: =F23 -> 191000 | O23: =IF(OR(N23=" ",N23=0)," ",$O$9) -> 0.8 | P23: =IF(OR(N23=" ",N23=0)," ",+ROUNDDOWN(N23*O23,0)) -> 152800 | R23: =Q23*($R$9) -> 0 | S23: =R23*0.19 -> 0 | T23: =+P23+R23+S23 -> 152800 | U23: =ROUNDDOWN(T23,-3) -> 152000
A24: 15 | B24: ON,OFF集中コントローラー | C24: 1 | D24: 個 | F24: 53000 | G24: =IF(F24=0," ",C24*F24) -> 53000 | I24: 83000 | J24: =IF(I24=0," ",C24*I24) -> 83000 | M24: =IF(C24=" "," ",C24*L24) -> 0 | N24: =F24 -> 53000 | O24: =IF(OR(N24=" ",N24=0)," ",$O$9) -> 0.8 | P24: =IF(OR(N24=" ",N24=0)," ",+ROUNDDOWN(N24*O24,0)) -> 42400 | R24: =Q24*($R$9) -> 0 | S24: =R24*0.19 -> 0 | T24: =+P24+R24+S24 -> 42400 | U24: =ROUNDDOWN(T24,-2) -> 42400
B25: 合 計 | G25: =SUM(G10:G24) -> 44870200 | J25: =SUM(J10:J24) -> 41645400 | M25: =IF(K7=0," ",SUM(M10:M21)) | R25: =Q25*R9 -> 0 | S25: =R25*$M$5 -> 0

Sheet バルクタンク
A2: 工事名称： | B2: =表紙!A12 -> 大藪小学校屋内運動場空調設備設置工事
A3: 工事種別： | B3: バルクタンク
A4: 掛率種別： | D4: 80 | F4: ％
B5: バルクタンク＋加熱温水器 | G5: ※富士工器は消火器、温水配管別途工事なので不採用とする。 | N5: 採用メーカー名称 | U5: № | V5: 1
E6: 名 称 | N6: 伊藤工機 | Q6: ② 労 務 費 | S6: ③ | T6: 複合単価
A7: 名 称 | B7: 内 容 | C7: 数量 | D7: 単位 | E7: 伊藤工機 | H7: 富士工器 | K7: 大垣ガス | O7: 掛率 | P7: ① | Q7: 歩掛 | R7: 賃金／日 | S7: その他 | T7: ①+②+③ | U7: 決定単価 | V7: 備 考
E8: P. | F8: 単 価 | G8: 金 額 | H8: P. | I8: 単 価 | J8: 金 額 | K8: P. | L8: 単 価 | M8: 金 額 | N8: 最小価格 | P8: 採用価格 | Q8: 作業員 | S8: ②× | T8: （合 計）
O9: =D4/100 -> 0.8 | Q9: 設備機械工 | R9: 29000 | S9: 0.19
A10: 1 | B10: GBU-1 バルクタンク | C10: 1 | D10: 台 | F10: 1830000 | G10: =IF(F10=0," ",C10*F10) -> 1830000 | I10: 3200000 | J10: =IF(I10=0," ",C10*I10) -> 3200000 | M10: =IF(C10=" "," ",C10*L10) -> 0 | N10: =IF($N$6=" "," ",IF($N$6=$E$7,F10,IF($N$6=$H$7,I10,IF($N$6=$K$7,L10,0)))) -> 1830000 | O10: =IF(OR(N10=" ",N10=0)," ",$O$9) -> 0.8 | P10: =IF(OR(N10=" ",N10=0)," ",+ROUNDDOWN(N10*O10,0)) -> 1464000 | Q10: 5.5 | R10: =Q10*($R$9) -> 159500 | S10: =R10*0.19 -> 30305 | T10: =+P10+R10+S10 -> 1653805 | U10: =ROUNDDOWN(T10,-1) -> 1653800
A11: 2 | B11: 部材（熱源機.調整器含む） | C11: 1 | D11: 式 | F11: 1495370 | G11: =IF(F11=0," ",C11*F11) -> 1495370 | I11: =10000+22400+5000*4 -> 52400 | J11: =IF(I11=0," ",C11*I11) -> 52400 | N11: =IF($N$6=" "," ",IF($N$6=$E$7,F11,IF($N$6=$H$7,I11,IF($N$6=$K$7,L11,0)))) -> 1495370 | O11: =IF(OR(N11=" ",N11=0)," ",$O$9) -> 0.8 | P11: =IF(OR(N11=" ",N11=0)," ",+ROUNDDOWN(N11*O11,0)) -> 1196296 | Q11: 1.25 | R11: =Q11*($R$9) -> 36250 | S11: =R11*0.19 -> 6887.5 | T11: =+P11+R11+S11 -> 1239433.5 | U11: =ROUNDDOWN(T11,-1) -> 1239430
A12: 3 | B12: バルクシステム工場組込費用 | C12: 1 | D12: 式 | F12: 87200 | G12: =IF(F12=0," ",C12*F12) -> 87200 | I12: =26800+5000*10 -> 76800 | J12: =IF(I12=0," ",C12*I12) -> 76800 | N12: =IF($N$6=" "," ",IF($N$6=$E$7,F12,IF($N$6=$H$7,I12,IF($N$6=$K$7,L12,0)))) -> 87200 | O12: =IF(OR(N12=" ",N12=0)," ",$O$9) -> 0.8 | P12: =IF(OR(N12=" ",N12=0)," ",+ROUNDDOWN(N12*O12,0)) -> 69760 | T12: =+P12+R12+S12 -> 69760 | U12: =ROUNDDOWN(T12,-1) -> 69760
A13: 4 | B13: 送料（バルク貯槽） | C13: 1 | D13: 式 | F13: 80000 | G13: =IF(F13=0," ",C13*F13) -> 80000 | I13: 70000 | J13: =IF(I13=0," ",C13*I13) -> 70000 | N13: =IF($N$6=" "," ",IF($N$6=$E$7,F13,IF($N$6=$H$7,I13,IF($N$6=$K$7,L13,0)))) -> 80000 | O13: =IF(OR(N13=" ",N13=0)," ",$O$9) -> 0.8 | P13: =IF(OR(N13=" ",N13=0)," ",+ROUNDDOWN(N13*O13,0)) -> 64000 | T13: =+P13+R13+S13 -> 64000 | U13: =ROUNDDOWN(T13,-1) -> 64000
A14: 5 | B14: XH-611EB | C14: 1 | D14: 台 | F14: 26800 | G14: =IF(F14=0," ",C14*F14) -> 26800 | J14: =IF(I14=0," ",C14*I14) | N14: =IF($N$6=" "," ",IF($N$6=$E$7,F14,IF($N$6=$H$7,I14,IF($N$6=$K$7,L14,0)))) -> 26800 | O14: =IF(OR(N14=" ",N14=0)," ",$O$9) -> 0.8 | P14: =IF(OR(N14=" ",N14=0)," ",+ROUNDDOWN(N14*O14,0)) -> 21440 | T14: =+P14+R14+S14 -> 21440 | U14: =ROUNDDOWN(T14,-1) -> 21440
A15: 6 | B15: 熱源機架台 SUS製 | C15: 1 | D15: 台 | F15: 240000 | G15: =IF(F15=0," ",C15*F15) -> 240000 | I15: 36000 | J15: =IF(I15=0," ",C15*I15) -> 36000 | N15: =IF($N$6=" "," ",IF($N$6=$E$7,F15,IF($N$6=$H$7,I15,IF($N$6=$K$7,L15,0)))) -> 240000 | O15: =IF(OR(N15=" ",N15=0)," ",$O$9) -> 0.8 | P15: =IF(OR(N15=" ",N15=0)," ",+ROUNDDOWN(N15*O15,0)) -> 192000 | T15: =+P15+R15+S15 -> 192000 | U15: =ROUNDDOWN(T15,-1) -> 192000
A16: 7 | B16: 配管カバー | C16: 1 | D16: 台 | F16: 14000 | G16: =IF(F16=0," ",C16*F16) -> 14000 | J16: =IF(I16=0," ",C16*I16) | N16: =IF($N$6=" "," ",IF($N$6=$E$7,F16,IF($N$6=$H$7,I16,IF($N$6=$K$7,L16,0)))) -> 14000 | O16: =IF(OR(N16=" ",N16=0)," ",$O$9) -> 0.8 | P16: =IF(OR(N16=" ",N16=0)," ",+ROUNDDOWN(N16*O16,0)) -> 11200 | T16: =+P16+R16+S16 -> 11200 | U16: =ROUNDDOWN(T16,-1) -> 11200
A17: 8 | B17: 消火器20型 | C17: 1 | D17: 本 | F17: 30400 | G17: =IF(F17=0," ",C17*F17) -> 30400 | J17: =IF(I17=0," ",C17*I17) | N17: =IF($N$6=" "," ",IF($N$6=$E$7,F17,IF($N$6=$H$7,I17,IF($N$6=$K$7,L17,0)))) -> 30400 | O17: =IF(OR(N17=" ",N17=0)," ",$O$9) -> 0.8 | P17: =IF(OR(N17=" ",N17=0)," ",+ROUNDDOWN(N17*O17,0)) -> 24320 | T17: =+P17+R17+S17 -> 24320 | U17: =ROUNDDOWN(T17,-1) -> 24320
A18: 9 | B18: 消火器BOX 20型1本用（SUS製） | C18: 1 | D18: 台 | F18: 23200 | G18: =IF(F18=0," ",C18*F18) -> 23200 | J18: =IF(I18=0," ",C18*I18) | N18: =IF($N$6=" "," ",IF($N$6=$E$7,F18,IF($N$6=$H$7,I18,IF($N$6=$K$7,L18,0)))) -> 23200 | O18: =IF(OR(N18=" ",N18=0)," ",$O$9) -> 0.8 | P18: =IF(OR(N18=" ",N18=0)," ",+ROUNDDOWN(N18*O18,0)) -> 18560 | T18: =+P18+R18+S18 -> 18560 | U18: =ROUNDDOWN(T18,-1) -> 18560
A19: 10 | B19: 警戒標識 LPガス供給設備（燃）（30-A） | C19: 1 | D19: 枚 | F19: 7540 | G19: =IF(F19=0," ",C19*F19) -> 7540 | I19: 3000 | J19: =IF(I19=0," ",C19*I19) -> 3000 | N19: =IF($N$6=" "," ",IF($N$6=$E$7,F19,IF($N$6=$H$7,I19,IF($N$6=$K$7,L19,0)))) -> 7540 | O19: =IF(OR(N19=" ",N19=0)," ",$O$9) -> 0.8 | P19: =IF(OR(N19=" ",N19=0)," ",+ROUNDDOWN(N19*O19,0)) -> 6032 | T19: =+P19+R19+S19 -> 6032 | U19: =ROUNDDOWN(T19,-1) -> 6030
A20: 11 | B20: 警戒標識 火気厳禁（10-B-二） | C20: 3 | D20: 枚 | F20: 4320 | G20: =IF(F20=0," ",C20*F20) -> 12960 | J20: =IF(I20=0," ",C20*I20) | N20: =IF($N$6=" "," ",IF($N$6=$E$7,F20,IF($N$6=$H$7,I20,IF($N$6=$K$7,L20,0)))) -> 4320 | O20: =IF(OR(N20=" ",N20=0)," ",$O$9) -> 0.8 | P20: =IF(OR(N20=" ",N20=0)," ",+ROUNDDOWN(N20*O20,0)) -> 3456 | T20: =+P20+R20+S20 -> 3456 | U20: =ROUNDDOWN(T20,-1) -> 3450
A21: 12 | B21: 警戒標識 立入禁止（12-D） | C21: 3 | D21: 枚 | F21: 4320 | G21: =IF(F21=0," ",C21*F21) -> 12960 | J21: =IF(I21=0," ",C21*I21) | N21: =IF($N$6=" "," ",IF($N$6=$E$7,F21,IF($N$6=$H$7,I21,IF($N$6=$K$7,L21,0)))) -> 4320 | O21: =IF(OR(N21=" ",N21=0)," ",$O$9) -> 0.8 | P21: =IF(OR(N21=" ",N21=0)," ",+ROUNDDOWN(N21*O21,0)) -> 3456 | T21: =+P21+R21+S21 -> 3456 | U21: =ROUNDDOWN(T21,-1) -> 3450
A22: 13 | B22: 温水配管、計装線工事 | C22: 1 | D22: 式 | F22: 500000 | G22: =IF(F22=0," ",C22*F22) -> 500000 | J22: =IF(I22=0," ",C22*I22) | N22: =IF($N$6=" "," ",IF($N$6=$E$7,F22,IF($N$6=$H$7,I22,IF($N$6=$K$7,L22,0)))) -> 500000 | O22: =IF(OR(N22=" ",N22=0)," ",$O$9) -> 0.8 | P22: =IF(OR(N22=" ",N22=0)," ",+ROUNDDOWN(N22*O22,0)) -> 400000 | T22: =+P22+R22+S22 -> 400000 | U22: =ROUNDDOWN(T22,-1) -> 400000
B24: 合 計 | G24: =IF(E7=0," ",SUM(G10:G23)) -> 4360430 | J24: =IF(H7=0," ",SUM(J10:J23)) -> 3438200 | M24: =IF(K7=0," ",SUM(M10:M23)) -> 0 | R24: =Q24*R9 -> 0 | S24: =R24*$M$5 -> 0

Sheet ガス工事　大垣ガス
A2: 工事名称： | B2: =表紙!A12 -> 大藪小学校屋内運動場空調設備設置工事
A3: 工事種別： | B3: ガス工事
A4: 掛率種別： | D4: 100 | F4: ％
B5: ガス工事（大垣ガス） | N5: 採用メーカー名称 | U5: № | V5: 1
E6: 名 称 | N6: 大垣ガス | Q6: ② 労 務 費 | S6: ③ | T6: 複合単価
A7: 名 称 | B7: 内 容 | C7: 数量 | D7: 単位 | E7: 大垣ガス | O7: 掛率 | P7: ① | Q7: 歩掛 | R7: 賃金／日 | S7: その他 | T7: ①+②+③ | U7: 決定単価 | V7: 備 考
E8: P. | F8: 単 価 | G8: 金 額 | H8: P. | I8: 単 価 | J8: 金 額 | K8: P. | L8: 単 価 | M8: 金 額 | N8: 最小価格 | P8: 採用価格 | Q8: 作業員 | S8: ②× | T8: （合 計）
O9: =D4/100 -> 1 | Q9: 設備機械工 | S9: 0.19
A10: 1 | B10: 基本工事 | C10: 1 | D10: 式 | F10: 28800 | G10: =IF(F10=0," ",C10*F10) -> 28800 | J10: =IF(I10=0," ",C10*I10) | M10: =IF(C10=" "," ",C10*L10) -> 0 | N10: =IF($N$6=" "," ",IF($N$6=$E$7,F10,IF($N$6=$H$7,I10,IF($N$6=$K$7,L10,0)))) -> 28800 | O10: =IF(OR(N10=" ",N10=0)," ",$O$9) -> 1 | P10: =IF(OR(N10=" ",N10=0)," ",+ROUNDDOWN(N10*O10,0)) -> 28800 | R10: =Q10*($R$9) -> 0 | S10: =R10*0.19 -> 0 | T10: =+P10+R10+S10 -> 28800 | U10: =ROUNDDOWN(T10,-1) -> 28800
A11: 2 | B11: ガス配管（被覆鋼管）VL20A | C11: 7 | D11: m | F11: 7500 | G11: =IF(F11=0," ",C11*F11) -> 52500 | N11: =IF($N$6=" "," ",IF($N$6=$E$7,F11,IF($N$6=$H$7,I11,IF($N$6=$K$7,L11,0)))) -> 7500 | O11: =IF(OR(N11=" ",N11=0)," ",$O$9) -> 1 | P11: =IF(OR(N11=" ",N11=0)," ",+ROUNDDOWN(N11*O11,0)) -> 7500 | R11: =Q11*($R$9) -> 0 | S11: =R11*0.19 -> 0 | T11: =+P11+R11+S11 -> 7500 | U11: =ROUNDDOWN(T11,-1) -> 7500
A12: 3 | B12: ガス配管（被覆鋼管）VL50A | C12: 23 | D12: m | F12: 17820 | G12: =IF(F12=0," ",C12*F12) -> 409860 | N12: =IF($N$6=" "," ",IF($N$6=$E$7,F12,IF($N$6=$H$7,I12,IF($N$6=$K$7,L12,0)))) -> 17820 | O12: =IF(OR(N12=" ",N12=0)," ",$O$9) -> 1 | P12: =IF(OR(N12=" ",N12=0)," ",+ROUNDDOWN(N12*O12,0)) -> 17820 | R12: =Q12*($R$9) -> 0 | S12: =R12*0.19 -> 0 | T12: =+P12+R12+S12 -> 17820 | U12: =ROUNDDOWN(T12,-1) -> 17820
A13: 4 | B13: 配管支持金具SUS | C13: 1 | D13: 式 | F13: 191300 | G13: =IF(F13=0," ",C13*F13) -> 191300 | N13: =IF($N$6=" "," ",IF($N$6=$E$7,F13,IF($N$6=$H$7,I13,IF($N$6=$K$7,L13,0)))) -> 191300 | O13: =IF(OR(N13=" ",N13=0)," ",$O$9) -> 1 | P13: =IF(OR(N13=" ",N13=0)," ",+ROUNDDOWN(N13*O13,0)) -> 191300 | R13: =Q13*($R$9) -> 0 | S13: =R13*0.19 -> 0 | T13: =+P13+R13+S13 -> 191300 | U13: =ROUNDDOWN(T13,-1) -> 191300
A14: 5 | B14: ガスフレキ50A-500 | C14: 1 | D14: 式 | F14: 28800 | G14: =IF(F14=0," ",C14*F14) -> 28800 | N14: =IF($N$6=" "," ",IF($N$6=$E$7,F14,IF($N$6=$H$7,I14,IF($N$6=$K$7,L14,0)))) -> 28800 | O14: =IF(OR(N14=" ",N14=0)," ",$O$9) -> 1 | P14: =IF(OR(N14=" ",N14=0)," ",+ROUNDDOWN(N14*O14,0)) -> 28800 | R14: =Q14*($R$9) -> 0 | S14: =R14*0.19 -> 0 | T14: =+P14+R14+S14 -> 28800 | U14: =ROUNDDOWN(T14,-1) -> 28800
A15: 6 | B15: 器具コック15A.GC15A | C15: 1 | D15: ケ | F15: 3650 | G15: =IF(F15=0," ",C15*F15) -> 3650 | N15: =IF($N$6=" "," ",IF($N$6=$E$7,F15,IF($N$6=$H$7,I15,IF($N$6=$K$7,L15,0)))) -> 3650 | O15: =IF(OR(N15=" ",N15=0)," ",$O$9) -> 1 | P15: =IF(OR(N15=" ",N15=0)," ",+ROUNDDOWN(N15*O15,0)) -> 3650 | R15: =Q15*($R$9) -> 0 | S15: =R15*0.19 -> 0 | T15: =+P15+R15+S15 -> 3650 | U15: =ROUNDDOWN(T15,-1) -> 3650
A16: 7 | B16: 強化ガスホース15A | C16: 1 | D16: 本 | F16: 4680 | G16: =IF(F16=0," ",C16*F16) -> 4680 | N16: =IF($N$6=" "," ",IF($N$6=$E$7,F16,IF($N$6=$H$7,I16,IF($N$6=$K$7,L16,0)))) -> 4680 | O16: =IF(OR(N16=" ",N16=0)," ",$O$9) -> 1 | P16: =IF(OR(N16=" ",N16=0)," ",+ROUNDDOWN(N16*O16,0)) -> 4680 | R16: =Q16*($R$9) -> 0 | S16: =R16*0.19 -> 0 | T16: =+P16+R16+S16 -> 4680 | U16: =ROUNDDOWN(T16,-1) -> 4680
A17: 8 | B17: 器具コック20A.GC20A | C17: 6 | D17: ケ | F17: 4830 | G17: =IF(F17=0," ",C17*F17) -> 28980 | N17: =IF($N$6=" "," ",IF($N$6=$E$7,F17,IF($N$6=$H$7,I17,IF($N$6=$K$7,L17,0)))) -> 4830 | O17: =IF(OR(N17=" ",N17=0)," ",$O$9) -> 1 | P17: =IF(OR(N17=" ",N17=0)," ",+ROUNDDOWN(N17*O17,0)) -> 4830 | R17: =Q17*($R$9) -> 0 | S17: =R17*0.19 -> 0 | T17: =+P17+R17+S17 -> 4830 | U17: =ROUNDDOWN(T17,-1) -> 4830
A18: 9 | B18: 強化ガスホース20A | C18: 6 | D18: 本 | F18: 8130 | G18: =IF(F18=0," ",C18*F18) -> 48780 | N18: =IF($N$6=" "," ",IF($N$6=$E$7,F18,IF($N$6=$H$7,I18,IF($N$6=$K$7,L18,0)))) -> 8130 | O18: =IF(OR(N18=" ",N18=0)," ",$O$9) -> 1 | P18: =IF(OR(N18=" ",N18=0)," ",+ROUNDDOWN(N18*O18,0)) -> 8130 | R18: =Q18*($R$9) -> 0 | S18: =R18*0.19 -> 0 | T18: =+P18+R18+S18 -> 8130 | U18: =ROUNDDOWN(T18,-1) -> 8130
A19: 10 | B19: ガスメーター10号 | C19: 1 | D19: 台 | F19: 118000 | G19: =IF(F19=0," ",C19*F19) -> 118000 | N19: =IF($N$6=" "," ",IF($N$6=$E$7,F19,IF($N$6=$H$7,I19,IF($N$6=$K$7,L19,0)))) -> 118000 | O19: =IF(OR(N19=" ",N19=0)," ",$O$9) -> 1 | P19: =IF(OR(N19=" ",N19=0)," ",+ROUNDDOWN(N19*O19,0)) -> 118000 | R19: =Q19*($R$9) -> 0 | S19: =R19*0.19 -> 0 | T19: =+P19+R19+S19 -> 118000 | U19: =ROUNDDOWN(T19,-1) -> 118000
A20: 11 | B20: メーターコック50A | C20: 2 | D20: ケ | F20: 13420 | G20: =IF(F20=0," ",C20*F20) -> 26840 | N20: =IF($N$6=" "," ",IF($N$6=$E$7,F20,IF($N$6=$H$7,I20,IF($N$6=$K$7,L20,0)))) -> 13420 | O20: =IF(OR(N20=" ",N20=0)," ",$O$9) -> 1 | P20: =IF(OR(N20=" ",N20=0)," ",+ROUNDDOWN(N20*O20,0)) -> 13420 | R20: =Q20*($R$9) -> 0 | S20: =R20*0.19 -> 0 | T20: =+P20+R20+S20 -> 13420 | U20: =ROUNDDOWN(T20,-1) -> 13420
A21: 12 | B21: メーター支持 | C21: 1 | D21: 式 | F21: 29500 | G21: =IF(F21=0," ",C21*F21) -> 29500 | N21: =IF($N$6=" "," ",IF($N$6=$E$7,F21,IF($N$6=$H$7,I21,IF($N$6=$K$7,L21,0)))) -> 29500 | O21: =IF(OR(N21=" ",N21=0)," ",$O$9) -> 1 | P21: =IF(OR(N21=" ",N21=0)," ",+ROUNDDOWN(N21*O21,0)) -> 29500 | R21: =Q21*($R$9) -> 0 | S21: =R21*0.19 -> 0 | T21: =+P21+R21+S21 -> 29500 | U21: =ROUNDDOWN(T21,-1) -> 29500
A22: 13 | B22: 小運搬費 | C22: 1 | D22: 式 | F22: 72880 | G22: =IF(F22=0," ",C22*F22) -> 72880 | N22: =IF($N$6=" "," ",IF($N$6=$E$7,F22,IF($N$6=$H$7,I22,IF($N$6=$K$7,L22,0)))) -> 72880 | O22: =IF(OR(N22=" ",N22=0)," ",$O$9) -> 1 | P22: =IF(OR(N22=" ",N22=0)," ",+ROUNDDOWN(N22*O22,0)) -> 72880 | R22: =Q22*($R$9) -> 0 | S22: =R22*0.19 -> 0 | T22: =+P22+R22+S22 -> 72880 | U22: =ROUNDDOWN(T22,-1) -> 72880
B24: 合 計 | G24: =IF(E7=0," ",SUM(G10:G23)) -> 1044570 | J24: =IF(H7=0," ",SUM(J10:J23)) | M24: =IF(K7=0," ",SUM(M10:M23)) | P24: =IF(N8=0," ",SUM(P10:P23)) -> 529310 | R24: =Q24*R9 -> 0 | S24: =R24*$M$5 -> 0 | U24: =IF(S7=0," ",SUM(U10:U23)) -> 529310

Sheet （計装工事） 
A1: ※この表は輪之内中の見積のまま（大藪小の計装メーカー見積は未入手）
A2: 工事名称： | B2: =表紙!A12 -> 大藪小学校屋内運動場空調設備設置工事
A3: 工事種別： | B3: 計装設備
A4: 掛率種別： | D4: 65 | F4: ％
B5: 計装設備 | F5: ※他社アズビル、ジョンソンコントロールズは見積辞退の連絡あり | N5: 採用メーカー名称 | U5: № | V5: 1
E6: 名 称 | N6: オーテック | Q6: ② 労 務 費 | S6: ③ | T6: 複合単価
A7: 名 称 | B7: 内 容 | C7: 数量 | D7: 単位 | E7: オーテック | O7: 掛率 | P7: ① | Q7: 歩掛 | R7: 賃金／日 | S7: その他 | T7: ①+②+③ | U7: 決定単価 | V7: 備 考
E8: P. | F8: 単 価 | G8: 金 額 | H8: P. | I8: 単 価 | J8: 金 額 | K8: P. | L8: 単 価 | M8: 金 額 | N8: 最小価格 | P8: 採用価格 | Q8: 作業員 | S8: ②× | T8: （合 計）
O9: =D4/100 -> 0.65 | Q9: 設備機械工 | R9: 29000 | S9: 0.19
A10: 1 | B10: SR-1自動制御盤 | C10: 1 | D10: 面 | F10: 2877000 | G10: =IF(F10=0," ",C10*F10) -> 2877000 | J10: =IF(I10=0," ",C10*I10) | M10: =IF(C10=" "," ",C10*L10) -> 0 | N10: =F10 -> 2877000 | O10: =IF(OR(N10=" ",N10=0)," ",$O$9) -> 0.65 | P10: =IF(OR(N10=" ",N10=0)," ",+ROUNDDOWN(N10*O10,0)) -> 1870050 | R10: =Q10*($R$9) -> 0 | S10: =R10*0.19 -> 0 | T10: =+P10+R10+S10 -> 1870050 | U10: =ROUNDDOWN(T10,1) -> 1870050
A11: 2 | B11: SR-2自動制御盤 | C11: 1 | D11: 面 | F11: 2731000 | G11: =IF(F11=0," ",C11*F11) -> 2731000 | J11: =IF(I11=0," ",C11*I11) | M11: =IF(C11=" "," ",C11*L11) -> 0 | N11: =IF($N$6=" "," ",IF($N$6=$E$7,F11,IF($N$6=$H$7,I11,IF($N$6=$K$7,L11,0)))) -> 2731000 | O11: =IF(OR(N11=" ",N11=0)," ",$O$9) -> 0.65 | P11: =IF(OR(N11=" ",N11=0)," ",+ROUNDDOWN(N11*O11,0)) -> 1775150 | T11: =+P11+R11+S11 -> 1775150 | U11: =ROUNDDOWN(T11,1) -> 1775150
A12: 3 | B12: 調整費 | C12: 1 | D12: 式 | F12: 842000 | G12: =IF(F12=0," ",C12*F12) -> 842000 | N12: =IF($N$6=" "," ",IF($N$6=$E$7,F12,IF($N$6=$H$7,I12,IF($N$6=$K$7,L12,0)))) -> 842000 | O12: =IF(OR(N12=" ",N12=0)," ",$O$9) -> 0.65 | P12: =IF(OR(N12=" ",N12=0)," ",+ROUNDDOWN(N12*O12,0)) -> 547300 | T12: =+P12+R12+S12 -> 547300 | U12: =ROUNDDOWN(T12,1) -> 547300
A13: 4 | B13: 付属ケーブル | G13: =IF(F13=0," ",C13*F13) | N13: =IF($N$6=" "," ",IF($N$6=$E$7,F13,IF($N$6=$H$7,I13,IF($N$6=$K$7,L13,0)))) -> 0 | O13: =IF(OR(N13=" ",N13=0)," ",$O$9) | P13: =IF(OR(N13=" ",N13=0)," ",+ROUNDDOWN(N13*O13,0)) | U13: =ROUNDDOWN(T13,1) -> 0
A14: 5 | B14: ケーブルEM-CEE1.25-2C | C14: 551 | D14: m | F14: 124 | G14: =IF(F14=0," ",C14*F14) -> 68324 | N14: =IF($N$6=" "," ",IF($N$6=$E$7,F14,IF($N$6=$H$7,I14,IF($N$6=$K$7,L14,0)))) -> 124 | O14: =IF(OR(N14=" ",N14=0)," ",$O$9) -> 0.65 | P14: =IF(OR(N14=" ",N14=0)," ",+ROUNDDOWN(N14*O14,0)) -> 80 | T14: =+P14+R14+S14 -> 80 | U14: =ROUNDDOWN(T14,1) -> 80
A15: 6 | B15: ケーブルEM-CEES1.25-2C | C15: 176 | D15: m | F15: 214 | G15: =IF(F15=0," ",C15*F15) -> 37664 | J15: =IF(I15=0," ",C15*I15) | M15: =IF(C15=" "," ",C15*L15) -> 0 | N15: =IF($N$6=" "," ",IF($N$6=$E$7,F15,IF($N$6=$H$7,I15,IF($N$6=$K$7,L15,0)))) -> 214 | O15: =IF(OR(N15=" ",N15=0)," ",$O$9) -> 0.65 | P15: =IF(OR(N15=" ",N15=0)," ",+ROUNDDOWN(N15*O15,0)) -> 139 | T15: =+P15+R15+S15 -> 139 | U15: =ROUNDDOWN(T15,1) -> 139
A16: 7 | B16: ケーブルEM-CEES1.25-6C | C16: 18 | D16: m | F16: 440 | G16: =IF(F16=0," ",C16*F16) -> 7920 | N16: =IF($N$6=" "," ",IF($N$6=$E$7,F16,IF($N$6=$H$7,I16,IF($N$6=$K$7,L16,0)))) -> 440 | O16: =IF(OR(N16=" ",N16=0)," ",$O$9) -> 0.65 | P16: =IF(OR(N16=" ",N16=0)," ",+ROUNDDOWN(N16*O16,0)) -> 286 | T16: =+P16+R16+S16 -> 286 | U16: =ROUNDDOWN(T16,1) -> 286
A17: 8 | B17: ケーブルEM-CEES1.25-7C | C17: 34 | D17: m | F17: 474 | G17: =IF(F17=0," ",C17*F17) -> 16116 | N17: =IF($N$6=" "," ",IF($N$6=$E$7,F17,IF($N$6=$H$7,I17,IF($N$6=$K$7,L17,0)))) -> 474 | O17: =IF(OR(N17=" ",N17=0)," ",$O$9) -> 0.65 | P17: =IF(OR(N17=" ",N17=0)," ",+ROUNDDOWN(N17*O17,0)) -> 308 | T17: =+P17+R17+S17 -> 308 | U17: =ROUNDDOWN(T17,1) -> 308
A18: 9 | B18: ケーブルEM-CE2.0-3C | C18: 3 | D18: m | F18: 221 | G18: =IF(F18=0," ",C18*F18) -> 663 | N18: =IF($N$6=" "," ",IF($N$6=$E$7,F18,IF($N$6=$H$7,I18,IF($N$6=$K$7,L18,0)))) -> 221 | O18: =IF(OR(N18=" ",N18=0)," ",$O$9) -> 0.65 | P18: =IF(OR(N18=" ",N18=0)," ",+ROUNDDOWN(N18*O18,0)) -> 143 | T18: =+P18+R18+S18 -> 143 | U18: =ROUNDDOWN(T18,1) -> 143
A19: 10 | B19: 電線管 E25 | C19: 2 | D19: 本 | F19: 1210 | G19: =IF(F19=0," ",C19*F19) -> 2420 | N19: =IF($N$6=" "," ",IF($N$6=$E$7,F19,IF($N$6=$H$7,I19,IF($N$6=$K$7,L19,0)))) -> 1210 | O19: =IF(OR(N19=" ",N19=0)," ",$O$9) -> 0.65 | P19: =IF(OR(N19=" ",N19=0)," ",+ROUNDDOWN(N19*O19,0)) -> 786 | T19: =+P19+R19+S19 -> 786 | U19: =ROUNDDOWN(T19,1) -> 786
A20: 11 | B20: 電線管 E31 | C20: 2 | D20: 本 | F20: 1710 | G20: =IF(F20=0," ",C20*F20) -> 3420 | N20: =IF($N$6=" "," ",IF($N$6=$E$7,F20,IF($N$6=$H$7,I20,IF($N$6=$K$7,L20,0)))) -> 1710 | O20: =IF(OR(N20=" ",N20=0)," ",$O$9) -> 0.65 | P20: =IF(OR(N20=" ",N20=0)," ",+ROUNDDOWN(N20*O20,0)) -> 1111 | T20: =+P20+R20+S20 -> 1111 | U20: =ROUNDDOWN(T20,1) -> 1111
A21: 12 | B21: 電線管 E51 | C21: 3 | D21: 本 | F21: 2900 | G21: =IF(F21=0," ",C21*F21) -> 8700 | N21: =IF($N$6=" "," ",IF($N$6=$E$7,F21,IF($N$6=$H$7,I21,IF($N$6=$K$7,L21,0)))) -> 2900 | O21: =IF(OR(N21=" ",N21=0)," ",$O$9) -> 0.65 | P21: =IF(OR(N21=" ",N21=0)," ",+ROUNDDOWN(N21*O21,0)) -> 1885 | T21: =+P21+R21+S21 -> 1885 | U21: =ROUNDDOWN(T21,1) -> 1885
A22: 13 | B22: 溶融亜鉛メッキ電線管 G22 | C22: 2 | D22: 本 | F22: 2330 | G22: =IF(F22=0," ",C22*F22) -> 4660 | N22: =IF($N$6=" "," ",IF($N$6=$E$7,F22,IF($N$6=$H$7,I22,IF($N$6=$K$7,L22,0)))) -> 2330 | O22: =IF(OR(N22=" ",N22=0)," ",$O$9) -> 0.65 | P22: =IF(OR(N22=" ",N22=0)," ",+ROUNDDOWN(N22*O22,0)) -> 1514 | T22: =+P22+R22+S22 -> 1514 | U22: =ROUNDDOWN(T22,1) -> 1514
A23: 14 | B23: 溶融亜鉛メッキ電線管 G28 | C23: 8 | D23: 本 | F23: 3150 | G23: =IF(F23=0," ",C23*F23) -> 25200 | N23: =IF($N$6=" "," ",IF($N$6=$E$7,F23,IF($N$6=$H$7,I23,IF($N$6=$K$7,L23,0)))) -> 3150 | O23: =IF(OR(N23=" ",N23=0)," ",$O$9) -> 0.65 | P23: =IF(OR(N23=" ",N23=0)," ",+ROUNDDOWN(N23*O23,0)) -> 2047 | T23: =+P23+R23+S23 -> 2047 | U23: =ROUNDDOWN(T23,1) -> 2047
A24: 15 | B24: 溶融亜鉛メッキ電線管 G36 | C24: 6 | D24: 本 | F24: 4076 | G24: =IF(F24=0," ",C24*F24) -> 24456 | N24: =IF($N$6=" "," ",IF($N$6=$E$7,F24,IF($N$6=$H$7,I24,IF($N$6=$K$7,L24,0)))) -> 4076 | O24: =IF(OR(N24=" ",N24=0)," ",$O$9) -> 0.65 | P24: =IF(OR(N24=" ",N24=0)," ",+ROUNDDOWN(N24*O24,0)) -> 2649 | T24: =+P24+R24+S24 -> 2649 | U24: =ROUNDDOWN(T24,1) -> 2649
A25: 16 | B25: 電線管付属品 | C25: 1 | D25: 式 | F25: 55100 | G25: =IF(F25=0," ",C25*F25) -> 55100 | J25: =IF(I25=0," ",C25*I25) | M25: =IF(C25=" "," ",C25*L25) -> 0 | N25: =IF($N$6=" "," ",IF($N$6=$E$7,F25,IF($N$6=$H$7,I25,IF($N$6=$K$7,L25,0)))) -> 55100 | O25: =IF(OR(N25=" ",N25=0)," ",$O$9) -> 0.65 | P25: =IF(OR(N25=" ",N25=0)," ",+ROUNDDOWN(N25*O25,0)) -> 35815 | T25: =+P25+R25+S25 -> 35815 | U25: =ROUNDDOWN(T25,1) -> 35815
A26: 17 | B26: プリカ＆コネクター類 | C26: 1 | D26: 式 | F26: 17300 | G26: =IF(F26=0," ",C26*F26) -> 17300 | N26: =IF($N$6=" "," ",IF($N$6=$E$7,F26,IF($N$6=$H$7,I26,IF($N$6=$K$7,L26,0)))) -> 17300 | O26: =IF(OR(N26=" ",N26=0)," ",$O$9) -> 0.65 | P26: =IF(OR(N26=" ",N26=0)," ",+ROUNDDOWN(N26*O26,0)) -> 11245 | T26: =+P26+R26+S26 -> 11245 | U26: =ROUNDDOWN(T26,1) -> 11245
A27: 18 | B27: 防水プルボックス250×250×250SUS | C27: 2 | D27: 個 | F27: 30400 | G27: =IF(F27=0," ",C27*F27) -> 60800 | N27: =IF($N$6=" "," ",IF($N$6=$E$7,F27,IF($N$6=$H$7,I27,IF($N$6=$K$7,L27,0)))) -> 30400 | O27: =IF(OR(N27=" ",N27=0)," ",$O$9) -> 0.65 | P27: =IF(OR(N27=" ",N27=0)," ",+ROUNDDOWN(N27*O27,0)) -> 19760 | T27: =+P27+R27+S27 -> 19760 | U27: =ROUNDDOWN(T27,1) -> 19760
A28: 19 | B28: 吊材料費及び指示具 | C28: 1 | D28: 式 | F28: 270400 | G28: =IF(F28=0," ",C28*F28) -> 270400 | N28: =IF($N$6=" "," ",IF($N$6=$E$7,F28,IF($N$6=$H$7,I28,IF($N$6=$K$7,L28,0)))) -> 270400 | O28: =IF(OR(N28=" ",N28=0)," ",$O$9) -> 0.65 | P28: =IF(OR(N28=" ",N28=0)," ",+ROUNDDOWN(N28*O28,0)) -> 175760 | T28: =+P28+R28+S28 -> 175760 | U28: =ROUNDDOWN(T28,1) -> 175760
A29: 20 | B29: 雑材料・消耗品 | C29: 1 | D29: 式 | F29: 102857 | G29: =IF(F29=0," ",C29*F29) -> 102857 | N29: =IF($N$6=" "," ",IF($N$6=$E$7,F29,IF($N$6=$H$7,I29,IF($N$6=$K$7,L29,0)))) -> 102857 | O29: =IF(OR(N29=" ",N29=0)," ",$O$9) -> 0.65 | P29: =IF(OR(N29=" ",N29=0)," ",+ROUNDDOWN(N29*O29,0)) -> 66857 | T29: =+P29+R29+S29 -> 66857 | U29: =ROUNDDOWN(T29,1) -> 66857
A30: 21 | B30: 機器取付費 | C30: 1 | D30: 式 | F30: 192000 | G30: =IF(F30=0," ",C30*F30) -> 192000 | N30: =IF($N$6=" "," ",IF($N$6=$E$7,F30,IF($N$6=$H$7,I30,IF($N$6=$K$7,L30,0)))) -> 192000 | O30: =IF(OR(N30=" ",N30=0)," ",$O$9) -> 0.65 | P30: =IF(OR(N30=" ",N30=0)," ",+ROUNDDOWN(N30*O30,0)) -> 124800 | T30: =+P30+R30+S30 -> 124800 | U30: =ROUNDDOWN(T30,1) -> 124800
A31: 22 | B31: 盤搬入費 | C31: 1 | D31: 式 | F31: 360000 | G31: =IF(F31=0," ",C31*F31) -> 360000 | N31: =IF($N$6=" "," ",IF($N$6=$E$7,F31,IF($N$6=$H$7,I31,IF($N$6=$K$7,L31,0)))) -> 360000 | O31: =IF(OR(N31=" ",N31=0)," ",$O$9) -> 0.65 | P31: =IF(OR(N31=" ",N31=0)," ",+ROUNDDOWN(N31*O31,0)) -> 234000 | T31: =+P31+R31+S31 -> 234000 | U31: =ROUNDDOWN(T31,1) -> 234000
A32: 23 | B32: 盤据付費 | C32: 1 | D32: 式 | F32: 432000 | G32: =IF(F32=0," ",C32*F32) -> 432000 | N32: =IF($N$6=" "," ",IF($N$6=$E$7,F32,IF($N$6=$H$7,I32,IF($N$6=$K$7,L32,0)))) -> 432000 | O32: =IF(OR(N32=" ",N32=0)," ",$O$9) -> 0.65 | P32: =IF(OR(N32=" ",N32=0)," ",+ROUNDDOWN(N32*O32,0)) -> 280800 | T32: =+P32+R32+S32 -> 280800 | U32: =ROUNDDOWN(T32,1) -> 280800
A33: 24 | B33: 結線費 | C33: 1 | D33: 式 | F33: 420000 | G33: =IF(F33=0," ",C33*F33) -> 420000 | N33: =IF($N$6=" "," ",IF($N$6=$E$7,F33,IF($N$6=$H$7,I33,IF($N$6=$K$7,L33,0)))) -> 420000 | O33: =IF(OR(N33=" ",N33=0)," ",$O$9) -> 0.65 | P33: =IF(OR(N33=" ",N33=0)," ",+ROUNDDOWN(N33*O33,0)) -> 273000 | T33: =+P33+R33+S33 -> 273000 | U33: =ROUNDDOWN(T33,1) -> 273000
A34: 25 | B34: 労務費 | C34: 1 | D34: 式 | F34: 3624000 | G34: =IF(F34=0," ",C34*F34) -> 3624000 | N34: =IF($N$6=" "," ",IF($N$6=$E$7,F34,IF($N$6=$H$7,I34,IF($N$6=$K$7,L34,0)))) -> 3624000 | O34: =IF(OR(N34=" ",N34=0)," ",$O$9) -> 0.65 | P34: =IF(OR(N34=" ",N34=0)," ",+ROUNDDOWN(N34*O34,0)) -> 2355600 | T34: =+P34+R34+S34 -> 2355600 | U34: =ROUNDDOWN(T34,1) -> 2355600
A35: 26 | B35: 雑工費 | C35: 1 | D35: 式 | F35: 866000 | G35: =IF(F35=0," ",C35*F35) -> 866000 | N35: =IF($N$6=" "," ",IF($N$6=$E$7,F35,IF($N$6=$H$7,I35,IF($N$6=$K$7,L35,0)))) -> 866000 | O35: =IF(OR(N35=" ",N35=0)," ",$O$9) -> 0.65 | P35: =IF(OR(N35=" ",N35=0)," ",+ROUNDDOWN(N35*O35,0)) -> 562900 | T35: =+P35+R35+S35 -> 562900 | U35: =ROUNDDOWN(T35,1) -> 562900
A36: 27 | B36: 試運転立会費 | C36: 1 | D36: 式 | F36: 182000 | G36: =IF(F36=0," ",C36*F36) -> 182000 | N36: =IF($N$6=" "," ",IF($N$6=$E$7,F36,IF($N$6=$H$7,I36,IF($N$6=$K$7,L36,0)))) -> 182000 | O36: =IF(OR(N36=" ",N36=0)," ",$O$9) -> 0.65 | P36: =IF(OR(N36=" ",N36=0)," ",+ROUNDDOWN(N36*O36,0)) -> 118300 | T36: =+P36+R36+S36 -> 118300 | U36: =ROUNDDOWN(T36,1) -> 118300
A37: 28 | B37: 機器・材料楊重費 | C37: 1 | D37: 式 | F37: 222000 | G37: =IF(F37=0," ",C37*F37) -> 222000 | N37: =IF($N$6=" "," ",IF($N$6=$E$7,F37,IF($N$6=$H$7,I37,IF($N$6=$K$7,L37,0)))) -> 222000 | O37: =IF(OR(N37=" ",N37=0)," ",$O$9) -> 0.65 | P37: =IF(OR(N37=" ",N37=0)," ",+ROUNDDOWN(N37*O37,0)) -> 144300 | T37: =+P37+R37+S37 -> 144300 | U37: =ROUNDDOWN(T37,1) -> 144300
... A39: 30 | B39: 廃材場内小運搬費 | C39: 1 | D39: 式 | F39: 91000 | G39: =IF(F39=0," ",C39*F39) -> 91000 | N39: =IF($N$6=" "," ",IF($N$6=$E$7,F39,IF($N$6=$H$7,I39,IF($N$6=$K$7,L39,0)))) -> 91000 | O39: =IF(OR(N39=" ",N39=0)," ",$O$9) -> 0.65 | P39: =IF(OR(N39=" ",N39=0)," ",+ROUNDDOWN(N39*O39,0)) -> 59150 | T39: =+P39+R39+S39 -> 59150 | U39: =ROUNDDOWN(T39,1) -> 59150
B40: 合 計 | G40: =SUM(G10:G39) -> 13878000 | J40: =IF(H7=0," ",SUM(J10:J22)) | M40: =IF(K7=0," ",SUM(M10:M22)) | R40: =Q40*R9 -> 0 | S40: =R40*$M$5 -> 0

Sheet 架台比較
A2: 工事名称： | B2: =表紙!A12 -> 大藪小学校屋内運動場空調設備設置工事
A3: 工事種別： | B3: 空調室外機架台
A4: 掛率種別： | D4: 70 | F4: ％
B5: 配管架台 | N5: 採用メーカー名称 | U5: № | V5: 1
E6: 名 称 | N6: 森松工業 | Q6: ② 労 務 費 | S6: ③ | T6: 複合単価
A7: 名 称 | B7: 内 容 | C7: 数量 | D7: 単位 | E7: 森松工業 | H7: 本荘工業 | K7: 石原工業 | O7: 掛率 | P7: ① | Q7: 歩掛 | R7: 賃金／日 | S7: その他 | T7: ①+②+③ | U7: 決定単価 | V7: 備 考
E8: P. | F8: 単 価 | G8: 金 額 | H8: P. | I8: 単 価 | J8: 金 額 | K8: P. | L8: 単 価 | M8: 金 額 | N8: 最小価格 | P8: 採用価格 | Q8: 作業員 | S8: ②× | T8: （合 計）
O9: =D4/100 -> 0.7 | Q9: 設備機械工 | R9: 29000 | S9: 0.19
A10: 1 | B10: 外部鉄骨架台 W1190×H2580 | C10: 1 | D10: 組 | F10: 660000 | G10: =IF(F10=0," ",C10*F10) -> 660000 | I10: =224000+95000+55000*2+148000*2 -> 725000 | J10: =IF(I10=0," ",C10*I10) -> 725000 | L10: =218000+92000+55000*2+144000*2 -> 708000 | M10: =IF(C10=" "," ",C10*L10) -> 708000 | N10: =IF($N$6=" "," ",IF($N$6=$E$7,F10,IF($N$6=$H$7,I10,IF($N$6=$K$7,L10,0)))) -> 660000 | O10: =IF(OR(N10=" ",N10=0)," ",$O$9) -> 0.7 | P10: =IF(OR(N10=" ",N10=0)," ",+ROUNDDOWN(N10*O10,0)) -> 462000 | Q10: 1.29 | R10: =Q10*($R$9) -> 37410 | S10: =R10*0.19 -> 7107.9 | T10: =+P10+R10+S10 -> 506517.9 | U10: =ROUNDDOWN(T10,0) -> 506517
A11: 2 | B11: 床置配管支持架台A-1 門型200×300 | C11: 1 | D11: 個 | F11: 14400 | G11: =IF(F11=0," ",C11*F11) -> 14400 | I11: 16000 | J11: =IF(I11=0," ",C11*I11) -> 16000 | L11: 15000 | M11: =IF(C11=" "," ",C11*L11) -> 15000 | N11: =IF($N$6=" "," ",IF($N$6=$E$7,F11,IF($N$6=$H$7,I11,IF($N$6=$K$7,L11,0)))) -> 14400 | O11: =IF(OR(N11=" ",N11=0)," ",$O$9) -> 0.7 | P11: =IF(OR(N11=" ",N11=0)," ",+ROUNDDOWN(N11*O11,0)) -> 10080 | Q11: 0.54 | R11: =Q11*($R$9) -> 15660 | S11: =R11*0.19 -> 2975.4 | T11: =+P11+R11+S11 -> 28715.4 | U11: =ROUNDDOWN(T11,0) -> 28715
A12: 3 | B12: 床置配管支持架台A-2 門型800×300 | C12: 6 | D12: 個 | F12: 25200 | G12: =IF(F12=0," ",C12*F12) -> 151200 | I12: 28000 | J12: =IF(I12=0," ",C12*I12) -> 168000 | L12: 27000 | M12: =IF(C12=" "," ",C12*L12) -> 162000 | N12: =IF($N$6=" "," ",IF($N$6=$E$7,F12,IF($N$6=$H$7,I12,IF($N$6=$K$7,L12,0)))) -> 25200 | O12: =IF(OR(N12=" ",N12=0)," ",$O$9) -> 0.7 | P12: =IF(OR(N12=" ",N12=0)," ",+ROUNDDOWN(N12*O12,0)) -> 17640 | Q12: 0.54 | R12: =Q12*($R$9) -> 15660 | S12: =R12*0.19 -> 2975.4 | T12: =+P12+R12+S12 -> 36275.4 | U12: =ROUNDDOWN(T12,0) -> 36275
A13: 4 | B13: 床置配管支持架台A-3 門型200×150 | C13: 10 | D13: 個 | F13: 9200 | G13: =IF(F13=0," ",C13*F13) -> 92000 | I13: 11000 | J13: =IF(I13=0," ",C13*I13) -> 110000 | L13: 10000 | M13: =IF(C13=" "," ",C13*L13) -> 100000 | N13: =IF($N$6=" "," ",IF($N$6=$E$7,F13,IF($N$6=$H$7,I13,IF($N$6=$K$7,L13,0)))) -> 9200 | O13: =IF(OR(N13=" ",N13=0)," ",$O$9) -> 0.7 | P13: =IF(OR(N13=" ",N13=0)," ",+ROUNDDOWN(N13*O13,0)) -> 6440 | Q13: 0.54 | R13: =Q13*($R$9) -> 15660 | S13: =R13*0.19 -> 2975.4 | T13: =+P13+R13+S13 -> 25075.4 | U13: =ROUNDDOWN(T13,0) -> 25075
A14: 5 | B14: 床置配管支持架台A-4 門型200×150 | C14: 32 | D14: 個 | F14: 9200 | G14: =IF(F14=0," ",C14*F14) -> 294400 | I14: 11000 | J14: =IF(I14=0," ",C14*I14) -> 352000 | L14: 10000 | M14: =IF(C14=" "," ",C14*L14) -> 320000 | N14: =IF($N$6=" "," ",IF($N$6=$E$7,F14,IF($N$6=$H$7,I14,IF($N$6=$K$7,L14,0)))) -> 9200 | O14: =IF(OR(N14=" ",N14=0)," ",$O$9) -> 0.7 | P14: =IF(OR(N14=" ",N14=0)," ",+ROUNDDOWN(N14*O14,0)) -> 6440 | Q14: 0.54 | R14: =Q14*($R$9) -> 15660 | S14: =R14*0.19 -> 2975.4 | T14: =+P14+R14+S14 -> 25075.4 | U14: =ROUNDDOWN(T14,0) -> 25075
A15: 6 | B15: 外壁配管支持架台B-1 ブラケット型1000×1000 | C15: 18 | D15: 個 | F15: 60800 | G15: =IF(F15=0," ",C15*F15) -> 1094400 | I15: 67000 | J15: =IF(I15=0," ",C15*I15) -> 1206000 | L15: 65000 | M15: =IF(C15=" "," ",C15*L15) -> 1170000 | N15: =IF($N$6=" "," ",IF($N$6=$E$7,F15,IF($N$6=$H$7,I15,IF($N$6=$K$7,L15,0)))) -> 60800 | O15: =IF(OR(N15=" ",N15=0)," ",$O$9) -> 0.7 | P15: =IF(OR(N15=" ",N15=0)," ",+ROUNDDOWN(N15*O15,0)) -> 42560 | Q15: 0.54 | R15: =Q15*($R$9) -> 15660 | S15: =R15*0.19 -> 2975.4 | T15: =+P15+R15+S15 -> 61195.4 | U15: =ROUNDDOWN(T15,0) -> 61195
A16: 7 | B16: 外壁配管支持架台B-2 1000 | C16: 33 | D16: 個 | F16: 18000 | G16: =IF(F16=0," ",C16*F16) -> 594000 | I16: 20000 | J16: =IF(I16=0," ",C16*I16) -> 660000 | L16: 19000 | M16: =IF(C16=" "," ",C16*L16) -> 627000 | N16: =IF($N$6=" "," ",IF($N$6=$E$7,F16,IF($N$6=$H$7,I16,IF($N$6=$K$7,L16,0)))) -> 18000 | O16: =IF(OR(N16=" ",N16=0)," ",$O$9) -> 0.7 | P16: =IF(OR(N16=" ",N16=0)," ",+ROUNDDOWN(N16*O16,0)) -> 12600 | Q16: 0.54 | R16: =Q16*($R$9) -> 15660 | S16: =R16*0.19 -> 2975.4 | T16: =+P16+R16+S16 -> 31235.4 | U16: =ROUNDDOWN(T16,0) -> 31235
A17: 8 | B17: 室内機防護カバー、防護架台 | C17: 14 | D17: 個 | F17: 948100 | G17: =IF(F17=0," ",C17*F17) -> 13273400 | I17: 1050000 | J17: =IF(I17=0," ",C17*I17) -> 14700000 | L17: 1020000 | M17: =IF(C17=" "," ",C17*L17) -> 14280000 | N17: =IF($N$6=" "," ",IF($N$6=$E$7,F17,IF($N$6=$H$7,I17,IF($N$6=$K$7,L17,0)))) -> 948100 | O17: =IF(OR(N17=" ",N17=0)," ",$O$9) -> 0.7 | P17: =IF(OR(N17=" ",N17=0)," ",+ROUNDDOWN(N17*O17,0)) -> 663670 | Q17: 0.54 | R17: =Q17*($R$9) -> 15660 | S17: =R17*0.19 -> 2975.4 | T17: =+P17+R17+S17 -> 682305.4 | U17: =ROUNDDOWN(T17,0) -> 682305
B25: 合 計 | G25: =SUM(G11:G24) -> 15513800 | J25: =IF(H7=0," ",SUM(J11:J24)) -> 17212000 | M25: =IF(K7=0," ",SUM(M11:M24)) -> 16674000 | R25: =Q25*R9 -> 0 | S25: =R25*$M$5 -> 0

Sheet 代価-1 
A1: 空調設備 代価表1-1 | C1: 配管保温工事
C2: =表紙!A12 -> 大藪小学校屋内運動場空調設備設置工事 | H2: 1-1
A3: 符号 | B3: 名 称 | C3: 摘 要 | D3: 数量 | E3: 単位 | F3: 単価 | G3: 金額 | H3: 備考
B4: 代価1-1
B5: 配管保温工事
B6: 冷媒配管、ドレン配管保温工事
B8: 冷媒管保温工事 | C8: 室外機配管 GW＋カラー亜鉛鉄板 100φ | D8: 232 | E8: m | F8: 10030 | G8: =D8*F8 -> 2326960 | H8: 積算マニュアル機械
B9: 冷媒管保温工事 | C9: 室内機露出配管 GW+塩ビ製樹脂カバー | E9: m | G9: =D9*F9 -> 0 | H9: 積算マニュアル機械
B15: 給水管保温工事 | C15: 屋外露出 GW＋SUS 20A | D15: 53 | E15: m | F15: 5610 | G15: =D15*F15 -> 297330 | H15: 積算マニュアル機械
B17: ドレン管保温工事 | C17: 屋内露出 保温化粧ケース25A | D17: 14 | E17: m | F17: 2940 | G17: =D17*F17 -> 41160 | H17: 積算マニュアル機械
B18: ドレン菅25A | C18: 天井内隠蔽 アルミガラスクロス25A | D18: 20 | E18: m | F18: 2430 | G18: =D18*F18 -> 48600 | H18: 積算マニュアル機械
B19: ドレン菅40A | C19: 天井内隠蔽 アルミガラスクロス40A | D19: 24 | E19: m | F19: 2790 | G19: =D19*F19 -> 66960 | H19: 積算マニュアル機械
B21: 計 | G21: =SUM(G4:G20) -> 2781010
B22: 端数処理 | G22: -1010
B23: 小計 | G23: =G21+G22 -> 2780000
A24: 空調設備 代価表1-2 | C24: 配管架台工事
C25: =C2 -> 大藪小学校屋内運動場空調設備設置工事 | H25: 1-2
A26: 符号 | B26: 名 称 | C26: 摘 要 | D26: 数量 | E26: 単位 | F26: 単価 | G26: 金額 | H26: 備考
B27: 代価1-2
B28: 配管架台工事
B30: 外壁架台 | D30: 1 | E30: ヵ所 | F30: =架台比較!U10 -> 506517 | G30: =D30*F30 -> 506517 | H30: 架台見積比較
B31: 架台A-1 | D31: 1 | E31: ヵ所 | F31: =架台比較!U11 -> 28715 | G31: =D31*F31 -> 28715 | H31: 架台見積比較
B32: 架台A-2 | D32: 6 | E32: ヵ所 | F32: =架台比較!U12 -> 36275 | G32: =D32*F32 -> 217650 | H32: 架台見積比較
B33: 架台A-3 | D33: 10 | E33: ヵ所 | F33: =架台比較!U13 -> 25075 | G33: =D33*F33 -> 250750 | H33: 架台見積比較
B34: 架台A-4 | D34: 32 | E34: ヵ所 | F34: =架台比較!U14 -> 25075 | G34: =D34*F34 -> 802400 | H34: 架台見積比較
B35: 架台B-1 | D35: 18 | E35: ヵ所 | F35: =架台比較!U15 -> 61195 | G35: =D35*F35 -> 1101510 | H35: 架台見積比較
B36: 架台B-2 | D36: 33 | E36: ヵ所 | F36: =架台比較!U16 -> 31235 | G36: =D36*F36 -> 1030755 | H36: 架台見積比較
B37: 空調室内機架台 | D37: 14 | E37: ヵ所 | F37: =架台比較!U17 -> 682305 | G37: =D37*F37 -> 9552270 | H37: 架台見積比較
B38: コンクリート | C38: 生コン人力打設 | D38: 0.3 | E38: m3 | F38: 40100 | G38: =D38*F38 -> 12030 | H38: 積算マニュアル機械
B39: 型枠 | D39: 13.5 | E39: m2 | F39: 11800 | G39: =D39*F39 -> 159300 | H39: 積算マニュアル機械
B40: 鉄筋 | C40: 1.04ｋｇ/ｍ | D40: 4 | E40: kg | F40: 320 | G40: =D40*F40 -> 1280 | H40: 積算マニュアル機械
F42: .
B44: 計 | G44: =SUM(G27:G43) -> 13663177
B45: 端数処理 | G45: -80557
B46: 小計 | G46: =ROUNDDOWN(G44+G45,-2) -> 13582600
A47: 空調設備 代価表-1-3 | C47: はつり貫通工事
C48: =C25 -> 大藪小学校屋内運動場空調設備設置工事 | H48: 1-3
A49: 符号 | B49: 名 称 | C49: 摘 要 | D49: 数量 | E49: 単位 | F49: 単価 | G49: 金額 | H49: 備考
B50: はつり貫通工事 | C50: 補修工事共
B52: L250×100φ | D52: 28 | E52: ヵ所 | G52: =D52*F52 -> 0 | H52: 積算マニュアル機械改修
...

Sheet 代価-2
A1: 空調設備 機器代価表2-1 | C1: 空調設備－機器搬入費
B2: 代価2-1 | C2: =表紙!A12 -> 大藪小学校屋内運動場空調設備設置工事 | N2: 2-1
A3: 名 称 | C3: 仕 様 | D3: 数量 | F3: 重量 | I3: 工費 | J3: 工費計① | M3: 合計
F4: ton | I4: 搬入規準単価
G5: 補正率 | L5: その他
A7: GHP-1 | B7: ガスヒートポンプマルチエアコン室外機 | C7: 型式：電源自立型20㏋、プロパン仕様 仕様：冷房能力56.0kw 暖房能力63.0kw 815kg 2.245*1.66*0.88=3.279 容積248.6kg | D7: 1 | F7: 0.815 | G7: 1.7 | I7: 85300 | J7: =D7*F7*G7*I7 -> 118183.15 | L7: =J7*0.2 -> 23636.63 | M7: =(J7+L7)*D7 -> 141819.78
I8: 300㎏/㎥未満
A10: GHP-2 | B10: ガスヒートポンプマルチエアコン室外機 | C10: 型式：電源自立型20㏋、プロパン仕様 仕様：冷房能力56.0kw 暖房能力63.0kw 815kg 2.245*1.66*0.88=3.279 容積248.6kg | D10: 1 | F10: 0.815 | G10: 1.7 | I10: 85300 | J10: =D10*F10*G10*I10 -> 118183.15 | L10: =J10*0.2 -> 23636.63 | M10: =(J10+L10)*D10 -> 141819.78
I11: 300㎏/㎥未満
A13: GHP-3 | B13: ガスヒートポンプマルチエアコン室外機 | C13: 型式：電源自立型20㏋、プロパン仕様 仕様：冷房能力56.0kw 暖房能力63.0kw 815kg 2.245*1.66*0.88=3.279 容積248.6kg | D13: 1 | F13: 0.815 | G13: 1.7 | I13: 85300 | J13: =D13*F13*G13*I13 -> 118183.15 | L13: =J13*0.2 -> 23636.63 | M13: =(J13+L13)*D13 -> 141819.78
I14: 300㎏/㎥未満
A16: GHP-4 | B16: ガスヒートポンプマルチエアコン室外機 | C16: 型式： 床置形 仕様： 冷房能力28.0kw暖房能力31.5kw 550kg 2.077*1.4*0.88=2.558 容積215.0kg | D16: 1 | F16: 0.55 | G16: 1.7 | I16: 85300 | J16: =D16*F16*G16*I16 -> 79755.5 | L16: =J16*0.2 -> 15951.1 | M16: =(J16+L16)*D16 -> 95706.6
I17: 300㎏/㎥未満
A47: 合計 | L47: 合計 | M47: =SUM(M6:M45) -> 521165.94
L48: 端数処理後 | M48: =ROUNDDOWN(M47,-3) -> 521000

Sheet 代価-3 
A1: 空調設備 代価表-3-1 | C1: 付帯工事－メッシュフェンス
C2: =表紙!A12 -> 大藪小学校屋内運動場空調設備設置工事 | H2: 3-1
A3: 符号 | B3: 名 称 | C3: 摘 要 | D3: 数量 | E3: 単位 | F3: 単価 | G3: 金額 | H3: 備考
B4: 代価3-1
B5: 撤去工事
B7: 冷媒配管撤去 | C7: 9.5 | D7: 42.6 | E7: m | F7: 24940 | G7: =D7*F7 -> 1062444 | H7: 積算マニュアル改修機械
B8: 冷媒配管撤去 | C8: 15.8 | D8: 42.6 | E8: m | F8: 24940 | G8: =D8*F8 -> 1062444 | H8: 積算マニュアル改修機械
B11: AC-1空調室外機撤去(架台共) | C11: ツインエアコン冷房20.0kw 暖房22.4ｋｗ | D11: 1 | E11: 台 | G11: =D11*F11 -> 0 | H11: 積算マニュアル改修機械
B12: AC-1空調室内機撤去 | C12: 天井カセット形 冷房10.0kw 暖房11.2ｋｗ | D12: 2 | E12: 台 | G12: =D12*F12 -> 0 | H12: 積算マニュアル改修機械
B13: AC-2空調室外機撤去(架台共) | C13: セパレートエアコン冷房10.0kw 暖房11.2ｋｗ | D13: 1 | E13: 台 | G13: =D13*F13 -> 0 | H13: 積算マニュアル改修機械
B14: AC-2空調室内機撤去 | C14: 天井カセット形 冷房10.0kw 暖房11.2ｋｗ | D14: 1 | E14: 台 | G14: =D14*F14 -> 0 | H14: 積算マニュアル改修機械
B21: 計 | G21: =SUM(G4:G20) -> 2124888
B22: 端数処理 | G22: -2444
B23: 小計 | G23: =G21+G22 -> 2122444
A24: 空調設備 代価表-3-2 | C24: 基礎工事
C25: =C2 -> 大藪小学校屋内運動場空調設備設置工事 | H25: 3-2
A26: 符号 | B26: 名 称 | C26: 摘 要 | D26: 数量 | E26: 単位 | F26: 単価 | G26: 金額 | H26: 備考
B27: 代価3-2
B28: バルクタンク塗装工事
E30: m2 | G30: =D30*F30 -> 0 | H30: 積算マニュアル機械
B44: 計 | G44: =SUM(G22:G43) -> 2120000
B45: 端数処理 | G45: -4618
B46: 小計 | G46: =ROUNDDOWN(G44+G45,-2) -> 2115300
A47: 空調設備 代価表-3-3 | C47: 基礎工事
C48: =C25 -> 大藪小学校屋内運動場空調設備設置工事 | H48: 3-2
A49: 符号 | B49: 名 称 | C49: 摘 要 | D49: 数量 | E49: 単位 | F49: 単価 | G49: 金額 | H49: 備考
B50: 代価3-3
B51: 配管接続工事
B53: 給水配管分岐接続工事 | C53: 20A-20A | D53: 1 | E53: ヵ所 | G53: =D53*F53 -> 0 | H53: 積算マニュアル改修機械
B67: 計 | G67: =SUM(G50:G66) -> 0
B68: 端数処理 | G68: -30
B69: 小計 | G69: =ROUNDDOWN(G67+G68,-2) -> 0
A70: 空調設備 代価表-3-4 | C70: 基礎工事
C71: =C48 -> 大藪小学校屋内運動場空調設備設置工事 | H71: 3-2
A72: 符号 | B72: 名 称 | C72: 摘 要 | D72: 数量 | E72: 単位 | F72: 単価 | G72: 金額 | H72: 備考
B73: 代価3-4
B74: 給水埋設管土工事
B76: 根切り | C76: 20A | E76: ｍ3 | G76: =D76*F76 -> 0 | H76: 積算マニュアル機械
B77: 埋め戻し | C77: 20A | E77: ｍ3 | G77: =D77*F77 -> 0 | H77: 積算マニュアル機械
B90: 計 | G90: =SUM(G73:G89) -> 0
...

Sheet E複合単価
A1: 複合単価作成表 | E1: ※輪之内中の盤見積のまま（大藪小の L-AC・S-AC は電気（明細）に記入）
A2: コードNo. | B2: 名 称 | D2: 内 容 | F2: 単位 | G2: 材料単価 | M2: 歩掛 | N2: 労務費(B) | O2: その他率 | P2: (A)+(B)+(C) | R2: 細 目 | S2: 適 用 | T2: 単位 | U2: 材料価格 | W2: 材料単価 | Y2: 塗装費
G3: 単価根拠 | H3: 数量 | I3: 補給率 | J3: 付属品 | K3: 雑材料率 | L3: 金額（A) | N3: 労務単価 | O3: その他(C) | P3: 丸め係数 | U3: カタログ | V3: 掛率 | W3: 単価 | X3: 単価/m
I4: (金額) | J4: (金額) | K4: (金額) | M4: 歩掛根拠 | N4: 労務費 | P4: 採用単価 | R4: 盤類単価：E見積比較、歩掛りは分電盤歩掛り。 器具類単価：E見積比較、歩掛りは積算基準
A5: 1 | C5: ='E見積比較(1)'!$B$5 -> 新設空調電源盤 | E5: ='E見積比較(1)'!$D$5 -> L-AC | F5: 面 | G5: ='E見積比較(1)'!$G$5 -> 992000 | H5: 1 | K5: 0.02 | L5: =IF(G5="","",(G5+K6)) -> 1011840 | M5: 5 | N5: =IF(G5="","",ROUNDDOWN(N7*M5,0)) -> 131500 | O5: 0.25 | P5: =IF(F5="","",L5+N5+O6) -> 1176215 | AA5: 1 | AB5: 見積比較
K6: =IF(H5="","",(G5*H5)*K5) -> 19840 | N6: =IF(G5="","",VLOOKUP(N8,人工費,2)) -> 電工 | O6: =IF(G5="","",ROUNDDOWN(N5*O5,0)) -> 32875 | P6: -4 | AA6: 2 | AB6: 建設物価
G7: =IF(G8="","",VLOOKUP(G8,単価根拠,2)) -> 見積比較 | M7: 積算実務 | N7: 26300 | O7: 積算基準 | P7: =IF(G5="","",ROUND(P5,P6)) -> 1180000 | AA7: 3 | AB7: 積算資料
G8: 1 | M8: マニュアル | N8: 1 | AA8: 4 | AB8: 平均単価 | AC8: （2,3の平均）
A9: 2 | C9: ='E見積比較(1)'!$B$6 -> 新設開閉器盤 | E9: ='E見積比較(1)'!D6 -> S-AC | F9: 面 | G9: ='E見積比較(1)'!$G$6 -> 104000 | H9: 1 | K9: 0.02 | L9: =IF(G9="","",(G9+K10)) -> 106080 | M9: 0.708 | N9: =IF(G9="","",ROUNDDOWN(N11*M9,0)) -> 18620 | O9: 0.25 | P9: =IF(F9="","",L9+N9+O10) -> 129355 | AA9: 5 | AB9: 見積書
K10: =IF(H9="","",(G9*H9)*K9) -> 2080 | N10: =IF(G9="","",VLOOKUP(N12,人工費,2)) -> 電工 | O10: =IF(G9="","",ROUNDDOWN(N9*O9,0)) -> 4655 | P10: -3 | AA10: 6 | AB10: カタログ
G11: =IF(G12="","",VLOOKUP(G12,単価根拠,2)) -> 見積比較 | M11: 積算実務 | N11: 26300 | O11: 積算基準 | P11: =IF(G9="","",ROUND(P9,P10)) -> 129000 | AA11: 7 | AB11: 積算ﾏﾆｱﾙ
G12: 1 | M12: マニュアル | N12: 1
AA20: 1 | AB20: 電工 | AC20: 24000
R21: 配管用基礎ブロック | S21: H:100 W:150 ゴムベース付 | T21: 個 | AA21: 2 | AB21: 特種作業員 | AC21: 26400
S22: ﾈｸﾞﾛｽ電工 | U22: 2925 | V22: 0.8 | W22: =U22*V22 -> 2340 | AA22: 3 | AB22: 普通作業員 | AC22: 22700
AA23: 4 | AB23: はつり工 | AC23: 28300
AA24: 5 | AB24: 配管工 | AC24: 24900
R25: 配管用基礎ブロック | S25: H:100 W:300 ゴムベース付 | T25: 個 | AA25: 6 | AB25: 設備機械工 | AC25: 29000
S26: ﾈｸﾞﾛｽ電工 | U26: 4780 | V26: 0.8 | W26: =U26*V26 -> 3824 | AA26: 7 | AB26: 塗装工 | AC26: 28800
AA27: 8 | AB27: とび工 | AC27: 30900
G28: 6 | N28: 1 | AA28: 9 | AB28: ダクト工 | AC28: 26600
AA29: 10 | AB29: 保温工 | AC29: 28200

Sheet E見積比較(1)
B1: 見積比較表 E(1) | D1: 分電盤 | F1: ※輪之内中の見積のまま
B3: 細 目 | D3: 摘 要 | E3: 単位 | F3: 数量 | G3: 決定単価 | H3: 掛率 | I3: 採用単価 | K3: 1 | L3: 内外電機 | M3: 2 | N3: 日東工業 | O3: 3 | P3: パナソニック
H4: 0.8 | I4: 1 | J4: を採用 | K4: 単価 | L4: 金額 | M4: 単価 | N4: 金額 | O4: 単価 | P4: 金額
B5: 新設空調電源盤 | D5: L-AC | E5: 面 | F5: 1 | G5: =ROUNDDOWN(H5*J5,-2) -> 992000 | H5: =H4 -> 0.8 | I5: =I4 -> 1 | J5: =K5 -> 1240000 | K5: 1240000 | L5: =F5*K5 -> 1240000 | M5: 1350000 | N5: =F5*M5 -> 1350000 | O5: 1400000 | P5: =F5*O5 -> 1400000
B6: 新設開閉器盤 | D6: S-AC | E6: 面 | F6: 1 | G6: =ROUNDDOWN(H6*J6,-2) -> 104000 | H6: =H5 -> 0.8 | I6: =I5 -> 1 | J6: =K6 -> 130000 | K6: 130000 | L6: =F6*K6 -> 130000 | M6: 150000 | N6: =F6*M6 -> 150000 | O6: 170000 | P6: =F6*O6 -> 170000
P7: =F7*O7 -> 0
P8: =F8*O8 -> 0
N9: =F9*M9 -> 0 | P9: =F9*O9 -> 0
N10: =F10*M10 -> 0 | P10: =F10*O10 -> 0
N11: =F11*M11 -> 0 | P11: =F11*O11 -> 0
G12: =ROUNDDOWN(H12*J12,-2) -> 0 | J12: =K12 -> 0 | L12: =F12*K12 -> 0 | N12: =F12*M12 -> 0 | P12: =F12*O12 -> 0
G14: =ROUNDDOWN(H14*J14,-2) -> 0 | J14: =K14 -> 0 | L14: =F14*K14 -> 0 | N14: =F14*M14 -> 0 | P14: =F14*O14 -> 0
G15: =ROUNDDOWN(H15*J15,-2) -> 0 | J15: =K15 -> 0 | L15: =F15*K15 -> 0 | N15: =F15*M15 -> 0 | P15: =F15*O15 -> 0
G16: =ROUNDDOWN(H16*J16,-2) -> 0 | J16: =K16 -> 0 | L16: =F16*K16 -> 0 | N16: =F16*M16 -> 0 | P16: =F16*O16 -> 0
G17: =ROUNDDOWN(H17*J17,-2) -> 0 | J17: =K17 -> 0 | L17: =F17*K17 -> 0 | N17: =M17*F17 -> 0 | P17: =O17*F17 -> 0
G18: =ROUNDDOWN(H18*J18,-2) -> 0 | J18: =K18 -> 0 | L18: =F18*K18 -> 0 | N18: =M18*F18 -> 0 | P18: =O18*F18 -> 0
G19: =ROUNDDOWN(H19*J19,-2) -> 0 | J19: =K19 -> 0 | L19: =F19*K19 -> 0 | N19: =M19*F19 -> 0 | P19: =O19*F19 -> 0
G20: =ROUNDDOWN(H20*J20,-2) -> 0 | J20: =K20 -> 0 | L20: =F20*K20 -> 0 | N20: =M20*F20 -> 0 | P20: =O20*F20 -> 0
G21: =ROUNDDOWN(H21*J21,-2) -> 0 | J21: =K21 -> 0 | L21: =F21*K21 -> 0 | N21: =M21*F21 -> 0 | P21: =O21*F21 -> 0
G22: =ROUNDDOWN(H22*J22,-2) -> 0 | J22: =K22 -> 0 | L22: =F22*K22 -> 0 | N22: =M22*F22 -> 0 | P22: =O22*F22 -> 0
G23: =ROUNDDOWN(H23*J23,-2) -> 0 | J23: =K23 -> 0 | L23: =F23*K23 -> 0 | N23: =M23*F23 -> 0 | P23: =O23*F23 -> 0
G24: =ROUNDDOWN(H24*J24,-2) -> 0 | J24: =K24 -> 0 | L24: =F24*K24 -> 0 | N24: =M24*F24 -> 0 | P24: =O24*F24 -> 0
G25: =ROUNDDOWN(H25*J25,-2) -> 0 | J25: =K25 -> 0 | L25: =F25*K25 -> 0 | N25: =M25*F25 -> 0 | P25: =O25*F25 -> 0
J26: =K26 -> 0 | L26: =F26*K26 -> 0 | N26: =M26*F26 -> 0 | P26: =O26*F26 -> 0
J27: =K27 -> 0 | L27: =F27*K27 -> 0 | N27: =M27*F27 -> 0 | P27: =O27*F27 -> 0
J28: =K28 -> 0 | L28: =F28*K28 -> 0 | N28: =M28*F28 -> 0 | P28: =O28*F28 -> 0
J29: =K29 -> 0 | L29: =F29*K29 -> 0 | N29: =M29*F29 -> 0 | P29: =O29*F29 -> 0
J30: =K30 -> 0 | L30: =F30*K30 -> 0 | N30: =M30*F30 -> 0 | P30: =O30*F30 -> 0
J31: =K31 -> 0 | L31: =F31*K31 -> 0 | N31: =M31*F31 -> 0 | P31: =O31*F31 -> 0
J32: =K32 -> 0 | L32: =F32*K32 -> 0 | N32: =M32*F32 -> 0 | P32: =O32*F32 -> 0
B33: =+B29 -> 0 | G33: =SUM(G5:G32) -> 1096000 | J33: =M33 -> 0 | L33: =F33*K33 -> 0 | N33: =M33*F33 -> 0 | P33: =O33*F33 -> 0
K34: =SUM(K5:K33) -> 1370000 | L34: =SUM(L5:L33) -> 1370000 | M34: =SUM(M5:M33) -> 1500000 | N34: =SUM(N5:N33) -> 1500000 | O34: =SUM(O5:O33) -> 1570000 | P34: =SUM(P5:P33) -> 1570000
K35: 1単価計 | L35: 1合計 | M35: 2単価計 | N35: 2合計 | O35: 3単価計 | P35: 3合計

Sheet E見積比較 (2)
B1: 見積比較表 E(2) | D1: プルボックス
B3: 細 目 | D3: 摘 要 | E3: 単位 | F3: 数量 | G3: 決定単価 | H3: 掛率 | I3: 採用単価 | K3: 1 | L3: 太暢金属 | M3: 2 | N3: 八州電工 | O3: 3
H4: 1 | I4: 1 | J4: を採用 | K4: 単価 | L4: 金額 | M4: 単価 | N4: 金額 | O4: 単価 | P4: 金額
B5: プルボックス(実勢価格) | D5: 200×200×200 | E5: 個 | F5: 1 | G5: =ROUNDDOWN(H5*J5,-2) -> 8200 | H5: =H4 -> 1 | I5: =I4 -> 1 | J5: =K5 -> 8200 | K5: 8200 | L5: =F5*K5 -> 8200 | M5: 15360 | N5: =F5*M5 -> 15360 | P5: =F5*O5 -> 0
B6: プルボックス(実勢価格) | D6: 300×300×300 | E6: 個 | F6: 1 | G6: =ROUNDDOWN(H6*J6,-2) -> 17000 | H6: =H5 -> 1 | I6: =I5 -> 1 | J6: =K6 -> 17000 | K6: 17000 | L6: =F6*K6 -> 17000 | M6: 29100 | N6: =F6*M6 -> 29100 | P6: =F6*O6 -> 0
P7: =F7*O7 -> 0
P8: =F8*O8 -> 0
N9: =F9*M9 -> 0 | P9: =F9*O9 -> 0
N10: =F10*M10 -> 0 | P10: =F10*O10 -> 0
N11: =F11*M11 -> 0 | P11: =F11*O11 -> 0
